Workbook

Sheet Assumptions
B1: Mem0 | Investment Case Model
B2: Tetration Ventures | US$ millions unless noted | Blue = input, Black = formula, Green = cross-sheet link | Prepared Jul 2026
B4: 1. Deal terms
B5: Entry post-money valuation ($mm) | C5: 120 | J5: Not disclosed by company. Triangulated: Letta seed was ~$70mm post with less traction; AI infra Series A norms $50mm+ post for category leaders. Flex me.
B6: Investment / check size ($mm) | C6: 1 | J6: Illustrative angel-AIF co-invest / SPV ticket. Flex me.
B7: Initial ownership % | C7: =C6/C5 -> 0.0083333333
B8: Holding period to exit (years) | C8: 5
B9: Entry year | C9: FY2026
B10: Exit year | C10: FY2031
B12: 2. Dilution to exit (future rounds; fund assumed not to follow on)
B13: Series B dilution % | C13: 0.22
B14: Series C dilution % | C14: 0.2
B15: Series D dilution % | C15: 0.18
B16: Cumulative ownership retained % | C16: =(1-C13)*(1-C14)*(1-C15) -> 0.51168
B17: Effective exit ownership % | C17: =C7*C16 -> 0.004264
B19: 3. FY2026E revenue build (bottoms-up, base case entry year)
B20: Self-serve paid accounts | C20: 1500 | J20: ~1.9% of 80k+ signed-up developers convert to paid. Source: 80k figure from TechCrunch, Oct 2025.
B21: Self-serve ARPA ($/yr) | C21: 3000 | J21: Blend of Pro ($249/mo ~ $3.0k/yr) and usage overage tiers. Source pricing: agenticwire / vectorize, 2026.
B22: Self-serve ARR ($mm) | C22: =C20*C21/1000000 -> 4.5
B23: Enterprise logos | C23: 18 | J23: Fortune 500 + AWS-driven pipeline. Source: 'Fortune 500 customers' TechCrunch/PRNewswire, Oct 2025.
B24: Enterprise ACV ($) | C24: 110000 | J24: Assumed land ACV for compliance-grade (SOC2/HIPAA) memory infra.
B25: Enterprise ARR ($mm) | C25: =C23*C24/1000000 -> 1.98
B26: FY2026E total ARR ($mm) | C26: =C22+C25 -> 6.48
B28: 4. ARR growth by scenario (YoY %)
C29: FY2027 | D29: FY2028 | E29: FY2029 | F29: FY2030 | G29: FY2031
B30: Bear | C30: 1.1 | D30: 0.7 | E30: 0.45 | F30: 0.3 | G30: 0.22
B31: Base | C31: 1.8 | D31: 1.2 | E31: 0.8 | F31: 0.55 | G31: 0.4
B32: Bull | C32: 2.4 | D32: 1.6 | E32: 1.1 | F32: 0.75 | G32: 0.55
B34: 5. Exit multiple (EV / forward ARR)
B35: Bear | C35: 7 | J35: Soft outcome / acqui-hire. AI infra can compress to high single digits.
B36: Base | C36: 12 | J36: AI-native infra median 25-30x ARR on growth names; 12x reflects size + maturity at exit. Source: qubit.capital, data-mania 2026.
B37: Bull | C37: 18 | J37: Category-defining, high-NRR consumption infra.
B39: 6. Market sizing inputs (2030)
B40: Paying AI 'app-equivalents' needing memory (millions) | C40: 1 | J40: Of ~4mm production AI-app builders by 2030, ~25% pay for memory infra.
B41: Avg annual memory spend per app ($) | C41: 6000
B42: Enterprise platform deployments | C42: 2000
B43: Avg enterprise platform spend ($) | C43: 250000
B44: SAM as % of TAM | C44: 0.55 | J44: Excludes fully in-house builds and big-lab-native-only memory.
B45: Mem0 SOM as % of SAM (FY2031, base) | C45: 0.045
B47: 7. Scenario probabilities
...

Sheet Market Sizing
B1: Market Sizing | TAM / SAM / SOM (2030)
B2: Bottoms-up. Working TAM kept deliberately conservative; external estimate shown as cross-check.
B4: Total addressable market (2030)
B5: TAM - developer / app-driven ($mm) | C5: =Assumptions!C40*Assumptions!C41 -> 6000 | E5: millions of apps x $ spend/app. Link: Assumptions inputs.
B6: TAM - enterprise platform ($mm) | C6: =Assumptions!C42*Assumptions!C43/1000000 -> 500
B7: TAM total ($mm) | C7: =C5+C6 -> 6500
B8: TAM total ($bn) | C8: =C7/1000 -> 6.5
B9: External estimate cross-check ($bn, 2030) | C9: 28.5 | E9: Source: agentmarketcap.ai, 2026 (secondary; treat as directional / aggressive).
B11: Serviceable market and share
B12: SAM ($mm) | C12: =C7*Assumptions!C44 -> 3575
B13: SOM - Mem0 base FY2031 ($mm) | C13: =C12*Assumptions!C45 -> 160.875
B14: Implied Mem0 base ARR as % of TAM | C14: ='Revenue Build'!H7/C7 -> 0.023986926 | E14: Base exit ARR / TAM. Sanity check: single-digit share needed.
B15: Implied Mem0 bull ARR as % of TAM | C15: ='Revenue Build'!H8/C7 -> 0.050199912

Sheet Revenue Build
B1: Revenue Build | ARR by scenario ($mm)
B2: All scenarios start from the same FY2026E bottoms-up base; growth rates from Assumptions.
B4: ARR ($mm) | C4: FY2026E | D4: FY2027E | E4: FY2028E | F4: FY2029E | G4: FY2030E | H4: FY2031E
B6: FY2026E base ARR (from build) | C6: =Assumptions!C26 -> 6.48
B7: Base | C7: =$C$6 -> 6.48 | D7: =C7*(1+Assumptions!C31) -> 18.144 | E7: =D7*(1+Assumptions!D31) -> 39.9168 | F7: =E7*(1+Assumptions!E31) -> 71.85024 | G7: =F7*(1+Assumptions!F31) -> 111.36787 | H7: =G7*(1+Assumptions!G31) -> 155.91502
B8: Bull | C8: =$C$6 -> 6.48 | D8: =C8*(1+Assumptions!C32) -> 22.032 | E8: =D8*(1+Assumptions!D32) -> 57.2832 | F8: =E8*(1+Assumptions!E32) -> 120.29472 | G8: =F8*(1+Assumptions!F32) -> 210.51576 | H8: =G8*(1+Assumptions!G32) -> 326.29943
B9: Bear | C9: =$C$6 -> 6.48 | D9: =C9*(1+Assumptions!C30) -> 13.608 | E9: =D9*(1+Assumptions!D30) -> 23.1336 | F9: =E9*(1+Assumptions!E30) -> 33.54372 | G9: =F9*(1+Assumptions!F30) -> 43.606836 | H9: =G9*(1+Assumptions!G30) -> 53.20034
B11: Note: base FY2031 ARR ties to Market Sizing SOM check.
B12: Revenue is usage + subscription (self-serve Pro + enterprise ACV + API consumption overage).

Sheet Returns
B1: Returns | Entry to exit, by scenario
B2: Exit equity value approximated by EV (minimal net debt at exit). $1.0mm illustrative ticket.
B4: Scenario | C4: Exit ARR ($mm) | D4: Exit multiple | E4: Exit EV ($mm) | F4: Exit own. % | G4: Proceeds ($mm) | H4: MOIC | I4: IRR
B5: Bear | C5: ='Revenue Build'!H9 -> 53.20034 | D5: =Assumptions!C35 -> 7 | E5: =C5*D5 -> 372.40238 | F5: =Assumptions!$C$17 -> 0.004264 | G5: =E5*F5 -> 1.5879237 | H5: =G5/Assumptions!$C$6 -> 1.5879237 | I5: =(G5/Assumptions!$C$6)^(1/Assumptions!$C$8)-1 -> 0.096897202
B6: Base | C6: ='Revenue Build'!H7 -> 155.91502 | D6: =Assumptions!C36 -> 12 | E6: =C6*D6 -> 1870.9802 | F6: =Assumptions!$C$17 -> 0.004264 | G6: =E6*F6 -> 7.9778598 | H6: =G6/Assumptions!$C$6 -> 7.9778598 | I6: =(G6/Assumptions!$C$6)^(1/Assumptions!$C$8)-1 -> 0.51487668
B7: Bull | C7: ='Revenue Build'!H8 -> 326.29943 | D7: =Assumptions!C37 -> 18 | E7: =C7*D7 -> 5873.3897 | F7: =Assumptions!$C$17 -> 0.004264 | G7: =E7*F7 -> 25.044134 | H7: =G7/Assumptions!$C$6 -> 25.044134 | I7: =(G7/Assumptions!$C$6)^(1/Assumptions!$C$8)-1 -> 0.90432559
B9: Prob-weighted | F9: Expected MOIC | H9: =Assumptions!C48*H5+Assumptions!C49*H6+Assumptions!C50*H7 -> 8.3013233
B10: Note: expected MOIC is tail-driven (typical of venture). Bear models a soft landing; a true category failure could impair most of the capital.
B13: Sensitivity: MOIC = Exit ARR x Multiple x Exit ownership / Invested
B14: Exit ARR \ Mult | C14: 6 | D14: 8 | E14: 10 | F14: 12 | G14: 15 | H14: 18
B15: 50 | C15: =$B15*6*Assumptions!$C$17/Assumptions!$C$6 -> 1.2792 | D15: =$B15*8*Assumptions!$C$17/Assumptions!$C$6 -> 1.7056 | E15: =$B15*10*Assumptions!$C$17/Assumptions!$C$6 -> 2.132 | F15: =$B15*12*Assumptions!$C$17/Assumptions!$C$6 -> 2.5584 | G15: =$B15*15*Assumptions!$C$17/Assumptions!$C$6 -> 3.198 | H15: =$B15*18*Assumptions!$C$17/Assumptions!$C$6 -> 3.8376
B16: 100 | C16: =$B16*6*Assumptions!$C$17/Assumptions!$C$6 -> 2.5584 | D16: =$B16*8*Assumptions!$C$17/Assumptions!$C$6 -> 3.4112 | E16: =$B16*10*Assumptions!$C$17/Assumptions!$C$6 -> 4.264 | F16: =$B16*12*Assumptions!$C$17/Assumptions!$C$6 -> 5.1168 | G16: =$B16*15*Assumptions!$C$17/Assumptions!$C$6 -> 6.396 | H16: =$B16*18*Assumptions!$C$17/Assumptions!$C$6 -> 7.6752
B17: 150 | C17: =$B17*6*Assumptions!$C$17/Assumptions!$C$6 -> 3.8376 | D17: =$B17*8*Assumptions!$C$17/Assumptions!$C$6 -> 5.1168 | E17: =$B17*10*Assumptions!$C$17/Assumptions!$C$6 -> 6.396 | F17: =$B17*12*Assumptions!$C$17/Assumptions!$C$6 -> 7.6752 | G17: =$B17*15*Assumptions!$C$17/Assumptions!$C$6 -> 9.594 | H17: =$B17*18*Assumptions!$C$17/Assumptions!$C$6 -> 11.5128
B18: 200 | C18: =$B18*6*Assumptions!$C$17/Assumptions!$C$6 -> 5.1168 | D18: =$B18*8*Assumptions!$C$17/Assumptions!$C$6 -> 6.8224 | E18: =$B18*10*Assumptions!$C$17/Assumptions!$C$6 -> 8.528 | F18: =$B18*12*Assumptions!$C$17/Assumptions!$C$6 -> 10.2336 | G18: =$B18*15*Assumptions!$C$17/Assumptions!$C$6 -> 12.792 | H18: =$B18*18*Assumptions!$C$17/Assumptions!$C$6 -> 15.3504
B19: 250 | C19: =$B19*6*Assumptions!$C$17/Assumptions!$C$6 -> 6.396 | D19: =$B19*8*Assumptions!$C$17/Assumptions!$C$6 -> 8.528 | E19: =$B19*10*Assumptions!$C$17/Assumptions!$C$6 -> 10.66 | F19: =$B19*12*Assumptions!$C$17/Assumptions!$C$6 -> 12.792 | G19: =$B19*15*Assumptions!$C$17/Assumptions!$C$6 -> 15.99 | H19: =$B19*18*Assumptions!$C$17/Assumptions!$C$6 -> 19.188
B20: 300 | C20: =$B20*6*Assumptions!$C$17/Assumptions!$C$6 -> 7.6752 | D20: =$B20*8*Assumptions!$C$17/Assumptions!$C$6 -> 10.2336 | E20: =$B20*10*Assumptions!$C$17/Assumptions!$C$6 -> 12.792 | F20: =$B20*12*Assumptions!$C$17/Assumptions!$C$6 -> 15.3504 | G20: =$B20*15*Assumptions!$C$17/Assumptions!$C$6 -> 19.188 | H20: =$B20*18*Assumptions!$C$17/Assumptions!$C$6 -> 23.0256
B21: 350 | C21: =$B21*6*Assumptions!$C$17/Assumptions!$C$6 -> 8.9544 | D21: =$B21*8*Assumptions!$C$17/Assumptions!$C$6 -> 11.9392 | E21: =$B21*10*Assumptions!$C$17/Assumptions!$C$6 -> 14.924 | F21: =$B21*12*Assumptions!$C$17/Assumptions!$C$6 -> 17.9088 | G21: =$B21*15*Assumptions!$C$17/Assumptions!$C$6 -> 22.386 | H21: =$B21*18*Assumptions!$C$17/Assumptions!$C$6 -> 26.8632

Sheet Comps & Sources
B1: Comparable transactions & sources
B2: Memory-layer and adjacent AI-infra rounds. Valuations largely undisclosed; estimates flagged.
B4: Company | C4: Category | D4: Stage | E4: Raised ($mm) | F4: Post-money | G4: Lead | H4: Date
B5: Mem0 | C5: AI memory layer | D5: Seed+A | E5: 24.0 | F5: ~$120mm (est) | G5: Kindred / Basis Set | H5: Oct 2025
B6: Letta (MemGPT) | C6: Agent memory / runtime | D6: Seed | E6: 10.0 | F6: $70mm (reported) | G6: Felicis | H6: 2025
B7: Supermemory | C7: AI memory API | D7: Seed | E7: 2.6 | F7: n/d | G7: Susa / Browder | H7: Oct 2025
B8: Zep | C8: Temporal memory graph | D8: Seed | E8: n/d (small) | F8: n/d | G8: Y Combinator | H8: 2024
B9: Braintrust | C9: AI eval infra (adj.) | D9: Growth | E9: 80.0 | F9: n/d | G9: n/d | H9: Feb 2026
B11: Read-across: Letta's $70mm seed post (less traction) supports a $100-150mm Series A post for Mem0 given AWS deal, category-leading community, and 5x API growth in two quarters.
B13: Sources
B14: [1] TechCrunch, 28 Oct 2025 - Mem0 raises $24M; $3.9M seed + $20M Series A; 41k stars, 14m downloads, 35m->186m API calls Q1->Q3 2025.
B15: [2] PR Newswire, 28 Oct 2025 - AWS chose Mem0 as exclusive memory provider for its Agent SDK; CrewAI/Flowise/Langflow native.
B16: [3] mem0.ai/series-a - company post; 'Plaid for memory' / memory passport vision.
B17: [4] Tracxn (May 2026) & PitchBook (2026) - HQ San Francisco; founded 2023; 22 employees (Apr 2026); total raised ~$24-25.5M; valuation gated.
B18: [5] agenticwire.news / vectorize.io / atlan.com (2026) - pricing (Pro $249/mo), benchmarks (LongMemEval), competitive landscape.
B19: [6] agentmarketcap.ai (2026) - agent-memory market $6.3bn (2025) -> $28.5bn (2030) at ~35% CAGR (secondary, directional).
B20: [7] qubit.capital / data-mania (2026) - AI Series A 15-30x revenue; AI-native platforms 25-30x ARR; median Series A post $30-35mm.
B22: Model notes & AI-use disclosure
B23: - Entry valuation, ARR, and all forward assumptions are estimates: Mem0's valuation and revenue are not public. Numbers are triangulated from the sources above and are meant to show reasoning, not precision.
B24: - Exit assumes equity value approx = EV (minimal net debt) and no fund follow-on (pure dilution to exit).
B25: - AI-use disclosure (adapt in your own words): research aggregation, model scaffolding, and first-draft assumptions were produced with an AI assistant. The candidate reviewed, revised, and owns the final assumptions, scenario logic, and recommendation.
