Workbook

Sheet README
B2: Project Apex — HCG (Healthcare Global) Leveraged Buyout Model
B4: Prepared for: Max Healthcare Office of the CEO ) | May 2026
B6: TRANSACTION SUMMARY
B7: Target | C7: Healthcare Global Enterprises Ltd. (HCG)
B8: Sector | C8: Healthcare — Specialty Oncology
B9: Geography | C9: Pan-India (22 cancer centers)
B10: Status | C10: Listed on NSE/BSE; ~76% controlled by KKR (via Aceso Co.)
B11: Enterprise Value | C11: ₹8,500 Cr (~$1.02 Bn at ₹83.5/$)
B12: Entry Multiple | C12: 22.4x FY25 EBITDA / 18.0x FY27E EBITDA
B13: Total Leverage | C13: ₹4,250 Cr (50% of EV) — 11.2x FY25 EBITDA
B14: Sponsor Equity | C14: ₹3,825 Cr (45% of Sources) — Max Healthcare
B15: Holding Period | C15: 5 years (close FY26 → exit FY31)
B16: Base Case Exit | C16: 18.0x EBITDA — IRR 29% / MOIC 3.6x (with synergies)
B18: SHEET MAP
B19: 1. README | C19: This sheet — overview, conventions, sheet map
B20: 2. Assumptions | C20: All hardcoded inputs (blue) with sourced rationale
B21: 3. Sources & Uses | C21: Transaction funding structure & purchase price build
B22: 4. Operating Model | C22: 5-year P&L: revenue build, EBITDA, capex, with synergies layer
B23: 5. Debt Schedule | C23: Senior TLB + Mezzanine schedule, mandatory amort + cash sweep
B24: 6. FCF & Returns | C24: FCF build, debt paydown, exit equity, IRR & MOIC waterfall
B25: 7. Comparables | C25: Trading multiples — listed Indian hospital peers (entry/exit anchor)
B26: 8. Precedents | C26: Recent healthcare M&A — entry multiple validation
B27: 9. Sensitivity | C27: IRR / MOIC sensitivities to entry × exit × leverage × synergy
B30: MODEL CONVENTIONS
B31: BLUE TEXT | C31: Hardcoded inputs / scenario drivers — these are the cells you change
B32: BLACK TEXT | C32: Formulas / calculations — do not overwrite
B33: GREEN TEXT | C33: Cross-sheet links pulling from another tab
B34: YELLOW FILL | C34: Key assumptions or cells flagged for case team attention
B35: (parentheses) | C35: Negative values shown with parentheses — accounting convention
B36: Units | C36: All ₹ figures in Crores (₹ Cr) unless stated; FX = ₹83.5/USD
B37: Fiscal Year | C37: Indian FY (April–March); FY25 = Apr'24–Mar'25; FY26 = Year 0 (close)

Sheet Assumptions
B2: Assumptions Tab — All Inputs & Rationale
B4: Driver | C4: Value | D4: Unit | E4: Source / Rationale
A5: # | B5: 1. TRANSACTION TERMS
B6: Target Enterprise Value | C6: 8500 | D6: ₹ Cr | E6: Implied 22.4x FY25 EBITDA — premium to ~17x trading multiple reflecting 76% control + scarcity
B7: Entry EV / FY25 EBITDA | C7: 22.4 | D7: x | E7: Triangulated from peers (Apollo 28x, KIMS 30x, Rainbow 32x) — discount for KKR exit + controlled mkt
B8: FX Rate (₹/$) | C8: 83.5 | D8: ₹/USD | E8: Bloomberg, INR/USD spot, May 2026
B9: Transaction Fees (% of EV) | C9: 0.022 | D9: % | E9: M&A advisor 1%, financing 0.7%, legal/DD 0.5% — Goldman benchmark for ₹8.5K Cr deal
B10: Min Cash to B/S at Close | C10: 200 | D10: ₹ Cr | E10: Working capital + 1 month opex buffer per credit committee
A12: # | B12: 2. CAPITAL STRUCTURE
B13: Senior TLB — Quantum | C13: 3400 | D13: ₹ Cr | E13: 40% of Sources; ~9.0x FY25 EBITDA — lender-tested ceiling for HC LBO in India
B14: Senior TLB — Tenor | C14: 5 | D14: years | E14: Bullet at maturity; matches sponsor hold; refinanceable Y3
B15: Senior TLB — Coupon (SOFR + bps) | C15: 0.11 | D15: % | E15: SOFR ~5.5% + 450bps = 11.0%; consistent with 2024-25 healthcare LBOs (Care, Hexagon)
B16: Senior TLB — Mandatory Amort | C16: 0.01 | D16: % / yr | E16: 1% per year mandatory; balance bullet — standard TLB structure
B17: Mezzanine — Quantum | C17: 850 | D17: ₹ Cr | E17: 10% of Sources; subordinated to TLB; PIK toggle
B18: Mezzanine — Coupon (cash + PIK) | C18: 0.145 | D18: % | E18: 14.5% blended (10% cash + 4.5% PIK accrual); priced at 350bps over TLB
B19: Sponsor Equity (Max Healthcare) | C19: 3825 | D19: ₹ Cr | E19: 45% of Sources; balance after debt + rollover
B20: Mgmt Rollover Equity | C20: 425 | D20: ₹ Cr | E20: 5% of Sources; aligns mgmt to long-term value (Dr. BS Ajaikumar et al.)
B21: Cash Sweep — % of Excess FCF | C21: 0.75 | D21: % | E21: 75% above min cash; standard TLB covenant (Indian LBO market)
B22: Min Cash Balance Threshold | C22: 150 | D22: ₹ Cr | E22: Operating buffer; below this, no sweep
A24: # | B24: 3. OPERATING — REVENUE BUILD
B25: FY25 Revenue (LTM) | C25: 2100 | D25: ₹ Cr | E25: HCG FY25 reported (annualized); IR investor presentation Q4 FY25
B26: Revenue Growth FY26 (Y0) | C26: 0.13 | D26: % | E26: Mid-case — moderated from initial estimates per CDD
B27: Revenue Growth FY27 (Y1) | C27: 0.13 | D27: % | E27: Specialty oncology growing 18-22% nationally; HCG comps growing 16-18%
B28: Revenue Growth FY28 (Y2) | C28: 0.12 | D28: % | E28: Maturing centers + Max network referrals begin
B29: Revenue Growth FY29 (Y3) | C29: 0.11 | D29: % | E29: Full network synergy realized + new center contributions
B30: Revenue Growth FY30 (Y4) | C30: 0.1 | D30: % | E30: Tapering; market share gains slow
B31: Revenue Growth FY31 (Y5) | C31: 0.09 | D31: % | E31: Tapering to long-run sector growth; mid-case
A33: # | B33: 4. OPERATING — MARGIN BUILD
B34: FY25 EBITDA Margin (LTM) | C34: 0.18 | D34: % | E34: HCG FY25 ~18% reported; mid-case scenario per BCG CDD benchmarks
B35: FY26 EBITDA Margin | C35: 0.183 | D35: % | E35: +100bps from new centers maturing past breakeven
B36: FY27 EBITDA Margin | C36: 0.187 | D36: % | E36: +100bps from procurement synergy Y1 (full year)
B37: FY28 EBITDA Margin | C37: 0.193 | D37: % | E37: +150bps revenue mix shift to high-end onco + cost synergies ramp
B38: FY29 EBITDA Margin | C38: 0.198 | D38: % | E38: +100bps full network procurement + Max GPO leverage
B39: FY30 EBITDA Margin | C39: 0.202 | D39: % | E39: +50bps continued mix shift; benchmarks at peer mid-quartile
B40: FY31 EBITDA Margin | C40: 0.205 | D40: % | E40: +25bps tail; mid-case below peer mid-quartile
A42: # | B42: 5. D&A, CAPEX & TAX
B43: D&A as % of Revenue | C43: 0.075 | D43: % | E43: Historical 7-8%; declines to 6.5% as capex normalizes
B44: Maintenance Capex (% of Revenue) | C44: 0.04 | D44: % | E44: Industry standard 3-5% for hospitals; HCG mid-cycle
B45: Growth Capex FY26 | C45: 250 | D45: ₹ Cr | E45: 2 new centers committed pre-deal (Mumbai Bandra, Lucknow)
B46: Growth Capex FY27 | C46: 200 | D46: ₹ Cr | E46: Bangalore expansion + Hyderabad upgrade
...

Sheet Sources_Uses
B2: Sources & Uses Schedule (₹ Cr)
B4: Transaction close: April 2026 (FY26 starting balance sheet)
A6: # | B6: SOURCES OF FUNDS | G6: USES OF FUNDS
B7: Source | C7: Amount (₹ Cr) | D7: % of Total | E7: x EBITDA | G7: Use | H7: Amount (₹ Cr) | I7: % of Total
B8: Senior Term Loan B (5-year) | C8: =Assumptions!C13 -> 3400 | D8: =C8/$C$12 -> 0.4 | E8: =C8/(Assumptions!C25*Assumptions!C34) -> 8.994709 | G8: Equity Purchase (76% KKR + minorities) | H8: =C12-H9-H10-H11 -> 7463 | I8: =H8/$H$12 -> 0.878
B9: Mezzanine / Subordinated Debt | C9: =Assumptions!C17 -> 850 | D9: =C9/$C$12 -> 0.1 | E9: =C9/(Assumptions!C25*Assumptions!C34) -> 2.2486772 | G9: Refinance Existing HCG Debt | H9: 650 | I9: =H9/$H$12 -> 0.076470588
B10: Sponsor Equity (Max Healthcare) | C10: =Assumptions!C19 -> 3825 | D10: =C10/$C$12 -> 0.45 | E10: — | G10: Cash to Balance Sheet (min cash) | H10: =Assumptions!C10 -> 200 | I10: =H10/$H$12 -> 0.023529412
B11: Mgmt Rollover Equity | C11: =Assumptions!C20 -> 425 | D11: =C11/$C$12 -> 0.05 | E11: — | G11: Transaction Fees & Expenses | H11: =Assumptions!C6*Assumptions!C9 -> 187 | I11: =H11/$H$12 -> 0.022
B12: Total Sources | C12: =SUM(C8:C11) -> 8500 | D12: =SUM(D8:D11) -> 1 | E12: =(C8+C9)/(Assumptions!C25*Assumptions!C34) -> 11.243386 | G12: Total Uses | H12: =SUM(H8:H11) -> 8500 | I12: =SUM(I8:I11) -> 1
A14: # | B14: CHECK: Sources = Uses | C14: =C12-H12 -> 0 | D14: =IF(ABS(C14)<0.5,"OK","ERROR") -> OK
A17: # | B17: PURCHASE PRICE BUILD-UP
B18: Enterprise Value | C18: =Assumptions!C6 -> 8500 | D18: Implied 22.4x FY25 EBITDA
B19: (+) Cash to B/S | C19: =Assumptions!C10 -> 200 | D19: Operating cushion
B20: (+) Transaction Fees | C20: =Assumptions!C6*Assumptions!C9 -> 187 | D20: M&A advisor + financing + legal
B21: (–) Existing Debt Refinanced | C21: -650 | D21: Net debt taken out at close
B22: (=) Total Funding Required | C22: =C18+C19+C20+C21 -> 8237 | D22: Equals Total Uses

Sheet Operating_Model
B2: HCG Operating Model — 5-Year Projection (₹ Cr)
B4: Driver / Line Item | C4: FY25A | D4: FY26 (Y0) | E4: FY27 (Y1) | F4: FY28 (Y2) | G4: FY29 (Y3) | H4: FY30 (Y4) | I4: FY31 (Y5)
A5: # | B5: STANDALONE OPERATING MODEL
B6: Revenue | C6: =Assumptions!C25 -> 2100 | D6: =C6*(1+Assumptions!C26) -> 2373 | E6: =D6*(1+Assumptions!C27) -> 2681.49 | F6: =E6*(1+Assumptions!C28) -> 3003.2688 | G6: =F6*(1+Assumptions!C29) -> 3333.6284 | H6: =G6*(1+Assumptions!C30) -> 3666.9912 | I6: =H6*(1+Assumptions!C31) -> 3997.0204
B7: Growth % | D7: =D6/C6-1 -> 0.13 | E7: =E6/D6-1 -> 0.13 | F7: =F6/E6-1 -> 0.12 | G7: =G6/F6-1 -> 0.11 | H7: =H6/G6-1 -> 0.1 | I7: =I6/H6-1 -> 0.09
B8: EBITDA (Standalone) | C8: =C6*Assumptions!C34 -> 378 | D8: =D6*Assumptions!C35 -> 434.259 | E8: =E6*Assumptions!C36 -> 501.43863 | F8: =F6*Assumptions!C37 -> 579.63088 | G8: =G6*Assumptions!C38 -> 660.05842 | H8: =H6*Assumptions!C39 -> 740.73222 | I8: =I6*Assumptions!C40 -> 819.38918
B9: EBITDA Margin % | C9: =C8/C6 -> 0.18 | D9: =D8/D6 -> 0.183 | E9: =E8/E6 -> 0.187 | F9: =F8/F6 -> 0.193 | G9: =G8/G6 -> 0.198 | H9: =H8/H6 -> 0.202 | I9: =I8/I6 -> 0.205
A11: # | B11: SYNERGIES (Incremental EBITDA from Max integration)
B12: Revenue Synergies | C12: 0 | D12: 0 | E12: =Assumptions!C53*Assumptions!C55 -> 36 | F12: =Assumptions!C53*Assumptions!C56 -> 99 | G12: =Assumptions!C53*Assumptions!C57 -> 180 | H12: =Assumptions!C53*Assumptions!C58 -> 198 | I12: =Assumptions!C53*Assumptions!C59 -> 207
B13: Cost Synergies | C13: 0 | D13: 0 | E13: =Assumptions!C54*Assumptions!C55 -> 20 | F13: =Assumptions!C54*Assumptions!C56 -> 55 | G13: =Assumptions!C54*Assumptions!C57 -> 100 | H13: =Assumptions!C54*Assumptions!C58 -> 110 | I13: =Assumptions!C54*Assumptions!C59 -> 115
B14: Total Synergies (incl.) | C14: =C12+C13 -> 0 | D14: =D12+D13 -> 0 | E14: =E12+E13 -> 56 | F14: =F12+F13 -> 154 | G14: =G12+G13 -> 280 | H14: =H12+H13 -> 308 | I14: =I12+I13 -> 322
B15: (–) Integration Cost | C15: 0 | D15: 0 | E15: -120 | F15: -80 | G15: 0 | H15: 0 | I15: 0
B16: Net Synergy Impact on EBITDA | C16: =C14+C15 -> 0 | D16: =D14+D15 -> 0 | E16: =E14+E15 -> -64 | F16: =F14+F15 -> 74 | G16: =G14+G15 -> 280 | H16: =H14+H15 -> 308 | I16: =I14+I15 -> 322
A18: # | B18: CONSOLIDATED P&L (Standalone + Synergies)
B19: Total Revenue | C19: =C6+C12 -> 2100 | D19: =D6+D12 -> 2373 | E19: =E6+E12 -> 2717.49 | F19: =F6+F12 -> 3102.2688 | G19: =G6+G12 -> 3513.6284 | H19: =H6+H12 -> 3864.9912 | I19: =I6+I12 -> 4204.0204
B20: Total EBITDA | C20: =C8+C16 -> 378 | D20: =D8+D16 -> 434.259 | E20: =E8+E16 -> 437.43863 | F20: =F8+F16 -> 653.63088 | G20: =G8+G16 -> 940.05842 | H20: =H8+H16 -> 1048.7322 | I20: =I8+I16 -> 1141.3892
B21: EBITDA Margin % | C21: =C20/C19 -> 0.18 | D21: =D20/D19 -> 0.183 | E21: =E20/E19 -> 0.16097157 | F21: =F20/F19 -> 0.21069447 | G21: =G20/G19 -> 0.26754634 | H21: =H20/H19 -> 0.27134143 | I21: =I20/I19 -> 0.27149944
B22: (–) D&A | C22: =-C19*Assumptions!C43 -> -157.5 | D22: =-D19*Assumptions!C43 -> -177.975 | E22: =-E19*Assumptions!C43 -> -203.81175 | F22: =-F19*Assumptions!C43 -> -232.67016 | G22: =-G19*Assumptions!C43 -> -263.52213 | H22: =-H19*Assumptions!C43 -> -289.87434 | I22: =-I19*Assumptions!C43 -> -315.30153
B23: EBIT | C23: =C20+C22 -> 220.5 | D23: =D20+D22 -> 256.284 | E23: =E20+E22 -> 233.62688 | F23: =F20+F22 -> 420.96072 | G23: =G20+G22 -> 676.53629 | H23: =H20+H22 -> 758.85788 | I23: =I20+I22 -> 826.08765
B24: (–) Interest Expense | C24: 0 | D24: =-Debt_Schedule!D23 -> -497.25 | E24: =-Debt_Schedule!E23 -> -499.05625 | F24: =-Debt_Schedule!F23 -> -501.11208 | G24: =-Debt_Schedule!G23 -> -503.42872 | H24: =-Debt_Schedule!H23 -> -506.01792 | I24: =-Debt_Schedule!I23 -> -508.89192
B25: Pre-Tax Income | C25: =C23+C24 -> 220.5 | D25: =D23+D24 -> -240.966 | E25: =E23+E24 -> -265.42937 | F25: =F23+F24 -> -80.151363 | G25: =G23+G24 -> 173.10756 | H25: =H23+H24 -> 252.83997 | I25: =I23+I24 -> 317.19573
B26: (–) Taxes | C26: =-MAX(C25,0)*Assumptions!C49 -> -55.566 | D26: =-MAX(D25,0)*Assumptions!C49 -> 0 | E26: =-MAX(E25,0)*Assumptions!C49 -> 0 | F26: =-MAX(F25,0)*Assumptions!C49 -> 0 | G26: =-MAX(G25,0)*Assumptions!C49 -> -43.623106 | H26: =-MAX(H25,0)*Assumptions!C49 -> -63.715671 | I26: =-MAX(I25,0)*Assumptions!C49 -> -79.933324
B27: Net Income | C27: =C25+C26 -> 164.934 | D27: =D25+D26 -> -240.966 | E27: =E25+E26 -> -265.42937 | F27: =F25+F26 -> -80.151363 | G27: =G25+G26 -> 129.48446 | H27: =H25+H26 -> 189.12429 | I27: =I25+I26 -> 237.26241
A29: # | B29: CAPEX & WORKING CAPITAL
B30: Maintenance Capex | C30: =C19*Assumptions!C44 -> 84 | D30: =D19*Assumptions!C44 -> 94.92 | E30: =E19*Assumptions!C44 -> 108.6996 | F30: =F19*Assumptions!C44 -> 124.09075 | G30: =G19*Assumptions!C44 -> 140.54513 | H30: =H19*Assumptions!C44 -> 154.59965 | I30: =I19*Assumptions!C44 -> 168.16082
B31: Growth Capex | C31: 0 | D31: =Assumptions!C45 -> 250 | E31: =Assumptions!C46 -> 200 | F31: =Assumptions!C47 -> 150 | G31: =Assumptions!C48 -> 100 | H31: =Assumptions!C48 -> 100 | I31: =Assumptions!C48 -> 100
B32: Total Capex | C32: =C30+C31 -> 84 | D32: =D30+D31 -> 344.92 | E32: =E30+E31 -> 308.6996 | F32: =F30+F31 -> 274.09075 | G32: =G30+G31 -> 240.54513 | H32: =H30+H31 -> 254.59965 | I32: =I30+I31 -> 268.16082
B33: Net Working Capital (NWC) | C33: =C19*Assumptions!C50 -> 168 | D33: =D19*Assumptions!C50 -> 189.84 | E33: =E19*Assumptions!C50 -> 217.3992 | F33: =F19*Assumptions!C50 -> 248.1815 | G33: =G19*Assumptions!C50 -> 281.09027 | H33: =H19*Assumptions!C50 -> 309.1993 | I33: =I19*Assumptions!C50 -> 336.32163
B34: (Increase) / Decrease in NWC | C34: 0 | D34: =-(D33-C33) -> -21.84 | E34: =-(E33-D33) -> -27.5592 | F34: =-(F33-E33) -> -30.782304 | G34: =-(G33-F33) -> -32.908765 | H34: =-(H33-G33) -> -28.109027 | I34: =-(I33-H33) -> -27.122337
A36: # | B36: KEY METRICS / VALUATION ANCHORS
B37: LTM EBITDA at Exit Year (₹ Cr) | C37: =I20 -> 1141.3892

Sheet Debt_Schedule
B2: Debt Schedule — Senior TLB + Mezzanine
B4: Tranche / Line Item | C4: Close FY26 | D4: FY26 | E4: FY27 | F4: FY28 | G4: FY29 | H4: FY30 | I4: FY31
A5: # | B5: SENIOR TERM LOAN B (5-year)
B6: Beginning Balance | C6: =Assumptions!C13 -> 3400 | D6: =C9 -> 3400 | E6: =D9 -> 3366 | F6: =E9 -> 3332 | G6: =F9 -> 3298 | H6: =G9 -> 3264 | I6: =H9 -> 3230
B7: (–) Mandatory Amortization | C7: 0 | D7: =-MIN(D6,Assumptions!C13*Assumptions!C16) -> -34 | E7: =-MIN(E6,Assumptions!C13*Assumptions!C16) -> -34 | F7: =-MIN(F6,Assumptions!C13*Assumptions!C16) -> -34 | G7: =-MIN(G6,Assumptions!C13*Assumptions!C16) -> -34 | H7: =-MIN(H6,Assumptions!C13*Assumptions!C16) -> -34 | I7: =-MIN(I6,Assumptions!C13*Assumptions!C16) -> -34
B8: (–) Optional Cash Sweep | C8: 0 | D8: =-MIN(D6+D7,MAX(0,FCF_Returns!D17)) -> 0 | E8: =-MIN(E6+E7,MAX(0,FCF_Returns!E17)) -> 0 | F8: =-MIN(F6+F7,MAX(0,FCF_Returns!F17)) -> 0 | G8: =-MIN(G6+G7,MAX(0,FCF_Returns!G17)) -> 0 | H8: =-MIN(H6+H7,MAX(0,FCF_Returns!H17)) -> 0 | I8: =-MIN(I6+I7,MAX(0,FCF_Returns!I17)) -> 0
B9: Ending Balance | C9: =C6 -> 3400 | D9: =SUM(D6:D8) -> 3366 | E9: =SUM(E6:E8) -> 3332 | F9: =SUM(F6:F8) -> 3298 | G9: =SUM(G6:G8) -> 3264 | H9: =SUM(H6:H8) -> 3230 | I9: =SUM(I6:I8) -> 3196
B10: (Avg Balance — informational) | D10: =AVERAGE(D6,D9) -> 3383 | E10: =AVERAGE(E6,E9) -> 3349 | F10: =AVERAGE(F6,F9) -> 3315 | G10: =AVERAGE(G6,G9) -> 3281 | H10: =AVERAGE(H6,H9) -> 3247 | I10: =AVERAGE(I6,I9) -> 3213
B11: Interest Expense | D11: =D6*Assumptions!C15 -> 374 | E11: =E6*Assumptions!C15 -> 370.26 | F11: =F6*Assumptions!C15 -> 366.52 | G11: =G6*Assumptions!C15 -> 362.78 | H11: =H6*Assumptions!C15 -> 359.04 | I11: =I6*Assumptions!C15 -> 355.3
A13: # | B13: MEZZANINE / SUB-DEBT (PIK toggle)
B14: Beginning Balance | C14: =Assumptions!C17 -> 850 | D14: =C17 -> 850 | E14: =D17 -> 888.25 | F14: =E17 -> 928.22125 | G14: =F17 -> 969.99121 | H14: =G17 -> 1013.6408 | I14: =H17 -> 1059.2546
B15: (+) PIK Accrual (4.5%) | C15: 0 | D15: =D14*0.045 -> 38.25 | E15: =E14*0.045 -> 39.97125 | F15: =F14*0.045 -> 41.769956 | G15: =G14*0.045 -> 43.649604 | H15: =H14*0.045 -> 45.613836 | I15: =I14*0.045 -> 47.666459
B16: (–) Repayment | C16: 0 | D16: 0 | E16: 0 | F16: 0 | G16: 0 | H16: 0 | I16: 0
B17: Ending Balance | C17: =C14 -> 850 | D17: =D14+D15+D16 -> 888.25 | E17: =E14+E15+E16 -> 928.22125 | F17: =F14+F15+F16 -> 969.99121 | G17: =G14+G15+G16 -> 1013.6408 | H17: =H14+H15+H16 -> 1059.2546 | I17: =I14+I15+I16 -> 1106.9211
B18: Cash Interest (10%) | D18: =D14*0.1 -> 85 | E18: =E14*0.1 -> 88.825 | F18: =F14*0.1 -> 92.822125 | G18: =G14*0.1 -> 96.999121 | H18: =H14*0.1 -> 101.36408 | I18: =I14*0.1 -> 105.92546
B19: Total Mezz Interest (cash + PIK) | D19: =D15+D18 -> 123.25 | E19: =E15+E18 -> 128.79625 | F19: =F15+F18 -> 134.59208 | G19: =G15+G18 -> 140.64872 | H19: =H15+H18 -> 146.97792 | I19: =I15+I18 -> 153.59192
A21: # | B21: TOTAL DEBT & INTEREST
B22: Total Debt (TLB + Mezz) | C22: =C9+C17 -> 4250 | D22: =D9+D17 -> 4254.25 | E22: =E9+E17 -> 4260.2213 | F22: =F9+F17 -> 4267.9912 | G22: =G9+G17 -> 4277.6408 | H22: =H9+H17 -> 4289.2546 | I22: =I9+I17 -> 4302.9211
B23: Total Interest Expense | C23: 0 | D23: =D11+D19 -> 497.25 | E23: =E11+E19 -> 499.05625 | F23: =F11+F19 -> 501.11208 | G23: =G11+G19 -> 503.42872 | H23: =H11+H19 -> 506.01792 | I23: =I11+I19 -> 508.89192
B25: Net Debt / EBITDA (Total Leverage) | C25: =IFERROR(C22/Operating_Model!C20,0) -> 11.243386 | D25: =IFERROR(D22/Operating_Model!D20,0) -> 9.796573 | E25: =IFERROR(E22/Operating_Model!E20,0) -> 9.7390147 | F25: =IFERROR(F22/Operating_Model!F20,0) -> 6.5296658 | G25: =IFERROR(G22/Operating_Model!G20,0) -> 4.5503989 | H25: =IFERROR(H22/Operating_Model!H20,0) -> 4.0899426 | I25: =IFERROR(I22/Operating_Model!I20,0) -> 3.7698983
B26: Senior Debt / EBITDA | C26: =IFERROR(C9/Operating_Model!C20,0) -> 8.994709 | D26: =IFERROR(D9/Operating_Model!D20,0) -> 7.7511347 | E26: =IFERROR(E9/Operating_Model!E20,0) -> 7.6170685 | F26: =IFERROR(F9/Operating_Model!F20,0) -> 5.0456613 | G26: =IFERROR(G9/Operating_Model!G20,0) -> 3.4721246 | H26: =IFERROR(H9/Operating_Model!H20,0) -> 3.0799092 | I26: =IFERROR(I9/Operating_Model!I20,0) -> 2.8000966
B27: Interest Coverage (EBITDA / Interest) | D27: =IFERROR(Operating_Model!D20/D23,0) -> 0.87332127 | E27: =IFERROR(Operating_Model!E20/E23,0) -> 0.87653171 | F27: =IFERROR(Operating_Model!F20/F23,0) -> 1.3043606 | G27: =IFERROR(Operating_Model!G20/G23,0) -> 1.8673118 | H27: =IFERROR(Operating_Model!H20/H23,0) -> 2.0725199 | I27: =IFERROR(Operating_Model!I20/I23,0) -> 2.2428911

Sheet FCF_Returns
B2: Free Cash Flow & Sponsor Returns
B4: Driver | C4: FY25A | D4: FY26 (Y0) | E4: FY27 (Y1) | F4: FY28 (Y2) | G4: FY29 (Y3) | H4: FY30 (Y4) | I4: FY31 (Y5)
A5: # | B5: FREE CASH FLOW BUILD
B6: EBITDA (incl. synergies) | C6: =Operating_Model!C20 -> 378 | D6: =Operating_Model!D20 -> 434.259 | E6: =Operating_Model!E20 -> 437.43863 | F6: =Operating_Model!F20 -> 653.63088 | G6: =Operating_Model!G20 -> 940.05842 | H6: =Operating_Model!H20 -> 1048.7322 | I6: =Operating_Model!I20 -> 1141.3892
B7: (–) Cash Interest | C7: 0 | D7: =-(Debt_Schedule!D11+Debt_Schedule!D18) -> -459 | E7: =-(Debt_Schedule!E11+Debt_Schedule!E18) -> -459.085 | F7: =-(Debt_Schedule!F11+Debt_Schedule!F18) -> -459.34213 | G7: =-(Debt_Schedule!G11+Debt_Schedule!G18) -> -459.77912 | H7: =-(Debt_Schedule!H11+Debt_Schedule!H18) -> -460.40408 | I7: =-(Debt_Schedule!I11+Debt_Schedule!I18) -> -461.22546
B8: (–) Cash Taxes | C8: 0 | D8: =-MAX(0,(Operating_Model!D23+Operating_Model!D24))*Assumptions!C49 -> 0 | E8: =-MAX(0,(Operating_Model!E23+Operating_Model!E24))*Assumptions!C49 -> 0 | F8: =-MAX(0,(Operating_Model!F23+Operating_Model!F24))*Assumptions!C49 -> 0 | G8: =-MAX(0,(Operating_Model!G23+Operating_Model!G24))*Assumptions!C49 -> -43.623106 | H8: =-MAX(0,(Operating_Model!H23+Operating_Model!H24))*Assumptions!C49 -> -63.715671 | I8: =-MAX(0,(Operating_Model!I23+Operating_Model!I24))*Assumptions!C49 -> -79.933324
B9: (–) Capex (Maint + Growth) | C9: =-Operating_Model!C32 -> -84 | D9: =-Operating_Model!D32 -> -344.92 | E9: =-Operating_Model!E32 -> -308.6996 | F9: =-Operating_Model!F32 -> -274.09075 | G9: =-Operating_Model!G32 -> -240.54513 | H9: =-Operating_Model!H32 -> -254.59965 | I9: =-Operating_Model!I32 -> -268.16082
B10: (–/+) Change in NWC | C10: =Operating_Model!C34 -> 0 | D10: =Operating_Model!D34 -> -21.84 | E10: =Operating_Model!E34 -> -27.5592 | F10: =Operating_Model!F34 -> -30.782304 | G10: =Operating_Model!G34 -> -32.908765 | H10: =Operating_Model!H34 -> -28.109027 | I10: =Operating_Model!I34 -> -27.122337
B11: (–) Mandatory Debt Amortization | C11: =Debt_Schedule!C7 -> 0 | D11: =Debt_Schedule!D7 -> -34 | E11: =Debt_Schedule!E7 -> -34 | F11: =Debt_Schedule!F7 -> -34 | G11: =Debt_Schedule!G7 -> -34 | H11: =Debt_Schedule!H7 -> -34 | I11: =Debt_Schedule!I7 -> -34
B12: Levered FCF (pre-sweep) | C12: =SUM(C6:C11) -> 294 | D12: =SUM(D6:D11) -> -425.501 | E12: =SUM(E6:E11) -> -391.90517 | F12: =SUM(F6:F11) -> -144.5843 | G12: =SUM(G6:G11) -> 129.20229 | H12: =SUM(H6:H11) -> 207.9038 | I12: =SUM(I6:I11) -> 270.94724
A14: # | B14: CASH BALANCE WALK & SWEEP
B15: Beginning Cash | C15: =Assumptions!C10 -> 200 | D15: =C19 -> 494 | E15: =D19 -> 68.499 | F15: =E19 -> -323.40617 | G15: =F19 -> -467.99047 | H15: =G19 -> -338.78818 | I15: =H19 -> -130.88439
B16: (+) Levered FCF | C16: =C12 -> 294 | D16: =D12 -> -425.501 | E16: =E12 -> -391.90517 | F16: =F12 -> -144.5843 | G16: =G12 -> 129.20229 | H16: =H12 -> 207.9038 | I16: =I12 -> 270.94724
B17: Available for Sweep (above min cash) | C17: 0 | D17: =MAX(0,D15+D16-Assumptions!C22)*Assumptions!C21 -> 0 | E17: =MAX(0,E15+E16-Assumptions!C22)*Assumptions!C21 -> 0 | F17: =MAX(0,F15+F16-Assumptions!C22)*Assumptions!C21 -> 0 | G17: =MAX(0,G15+G16-Assumptions!C22)*Assumptions!C21 -> 0 | H17: =MAX(0,H15+H16-Assumptions!C22)*Assumptions!C21 -> 0 | I17: =MAX(0,I15+I16-Assumptions!C22)*Assumptions!C21 -> 0
B18: (–) Cash Sweep to Debt | C18: 0 | D18: =Debt_Schedule!D8 -> 0 | E18: =Debt_Schedule!E8 -> 0 | F18: =Debt_Schedule!F8 -> 0 | G18: =Debt_Schedule!G8 -> 0 | H18: =Debt_Schedule!H8 -> 0 | I18: =Debt_Schedule!I8 -> 0
B19: Ending Cash | C19: =C15+C16+C18 -> 494 | D19: =D15+D16+D18 -> 68.499 | E19: =E15+E16+E18 -> -323.40617 | F19: =F15+F16+F18 -> -467.99047 | G19: =G15+G16+G18 -> -338.78818 | H19: =H15+H16+H18 -> -130.88439 | I19: =I15+I16+I18 -> 140.06286
A21: # | B21: EXIT EQUITY VALUE WATERFALL (FY31 / Year 5)
B22: Component | C22: Value (₹ Cr) | D22: Notes
B23: Exit LTM EBITDA (FY31, incl. synergies) | C23: =Operating_Model!I20 -> 1141.3892 | D23: From Operating Model row 20
B24: × Exit Multiple (Base case) | C24: =Assumptions!C63 -> 18 | D24: FY30 EV/EBITDA at exit
B25: (=) Exit Enterprise Value | C25: =C23*C24 -> 20545.005 | D25: EBITDA × Multiple
B26: (–) Net Debt at Exit (TLB + Mezz Ending) | C26: =-Debt_Schedule!I22 -> -4302.9211 | D26: From Debt Schedule
B27: (+) Cash at Exit | C27: =FCF_Returns!I19 -> 140.06286 | D27: From cash walk
B28: (=) Exit Equity Value | C28: =C25+C26+C27 -> 16382.147 | D28: Total equity to all sponsors
B29: (–) Mgmt Rollover Share (5%) | C29: =-C28*Assumptions!C20/(Assumptions!C19+Assumptions!C20) -> -1638.2147 | D29: Pro-rata to management
B30: (=) Equity to Max Healthcare Sponsor | C30: =C28+C29 -> 14743.932 | D30: Net to Max Healthcare
A32: # | B32: SPONSOR RETURNS — MAX HEALTHCARE
B33: Metric | C33: Value | D33: Notes
B34: Sponsor Equity Investment (Max) | C34: =-Assumptions!C19 -> -3825 | D34: Initial cash equity at close (₹ Cr)
B35: Equity Proceeds at Exit (Max) | C35: =C30 -> 14743.932 | D35: From exit waterfall (₹ Cr)
B36: Hold Period (years) | C36: =Assumptions!C66 -> 5 | D36: Years
B37: MOIC (Multiple of Invested Capital) | C37: =C35/-C34 -> 3.8546228 | D37: Exit / Invested
B38: IRR (Internal Rate of Return) | C38: =(C35/-C34)^(1/C36)-1 -> 0.30977404 | D38: Annualized return

Sheet Comparables
B2: Trading Comparables — Listed Indian Hospital Peers
B3: Source: NSE/BSE filings, Bloomberg consensus, company IR — figures as of May 2026 | All ₹ in Cr unless noted
B5: Company | C5: Mkt Cap (₹ Cr) | D5: Net Debt (₹ Cr) | E5: EV (₹ Cr) | F5: FY25 Rev (₹ Cr) | G5: FY25 EBITDA (₹ Cr) | H5: EBITDA Margin | I5: EV / FY25 EBITDA | J5: EV / FY27E EBITDA
B6: Apollo Hospitals | C6: 165000 | D6: 5500 | E6: =C6+D6 -> 170500 | F6: 22500 | G6: 6100 | H6: =G6/F6 -> 0.27111111 | I6: =E6/G6 -> 27.95082 | J6: =E6/8800 -> 19.375
B7: Max Healthcare (acquirer) | C7: 95000 | D7: -1200 | E7: =C7+D7 -> 93800 | F7: 13000 | G7: 3150 | H7: =G7/F7 -> 0.24230769 | I7: =E7/G7 -> 29.777778 | J7: =E7/4600 -> 20.391304
B8: Fortis Healthcare | C8: 38500 | D8: 1100 | E8: =C8+D8 -> 39600 | F8: 8500 | G8: 1800 | H8: =G8/F8 -> 0.21176471 | I8: =E8/G8 -> 22 | J8: =E8/2750 -> 14.4
B9: Narayana Hrudayalaya | C9: 28500 | D9: 800 | E9: =C9+D9 -> 29300 | F9: 5640 | G9: 1395 | H9: =G9/F9 -> 0.24734043 | I9: =E9/G9 -> 21.003584 | J9: =E9/2150 -> 13.627907
B10: KIMS Hospitals | C10: 25000 | D10: 1500 | E10: =C10+D10 -> 26500 | F10: 2800 | G10: 945 | H10: =G10/F10 -> 0.3375 | I10: =E10/G10 -> 28.042328 | J10: =E10/1480 -> 17.905405
B11: Rainbow Children's | C11: 14500 | D11: -300 | E11: =C11+D11 -> 14200 | F11: 1420 | G11: 473 | H11: =G11/F11 -> 0.33309859 | I11: =E11/G11 -> 30.021142 | J11: =E11/720 -> 19.722222
B12: Aster DM Healthcare (India) | C12: 21000 | D12: 1800 | E12: =C12+D12 -> 22800 | F12: 4200 | G12: 1100 | H12: =G12/F12 -> 0.26190476 | I12: =E12/G12 -> 20.727273 | J12: =E12/1700 -> 13.411765
B13: Jupiter Hospital | C13: 10500 | D13: 600 | E13: =C13+D13 -> 11100 | F13: 1180 | G13: 395 | H13: =G13/F13 -> 0.33474576 | I13: =E13/G13 -> 28.101266 | J13: =E13/620 -> 17.903226
B14: HCG (target) | C14: 6500 | D14: 600 | E14: =C14+D14 -> 7100 | F14: 2100 | G14: 380 | H14: =G14/F14 -> 0.18095238 | I14: =E14/G14 -> 18.684211 | J14: =E14/555 -> 12.792793
B16: Peer Mean | H16: =AVERAGE(H6:H13) -> 0.27997163 | I16: =AVERAGE(I6:I13) -> 25.953024 | J16: =AVERAGE(J6:J13) -> 17.092104
B17: Peer Median | H17: =MEDIAN(H6:H13) -> 0.26650794 | I17: =MEDIAN(I6:I13) -> 27.996574 | J17: =MEDIAN(J6:J13) -> 17.904316
B18: Peer Min | H18: =MIN(H6:H13) -> 0.21176471 | I18: =MIN(I6:I13) -> 20.727273 | J18: =MIN(J6:J13) -> 13.411765
B19: Peer Max | H19: =MAX(H6:H13) -> 0.3375 | I19: =MAX(I6:I13) -> 30.021142 | J19: =MAX(J6:J13) -> 20.391304
B21: IMPLIED VALUATION FOR HCG (Target)
B22: Method | C22: Multiple | D22: Applied to (₹ Cr) | E22: Implied EV (₹ Cr) | F22: Implied Equity (₹ Cr) | G22: Notes
B23: Peer Median FY25 EV/EBITDA | C23: =I17 -> 27.996574 | D23: 380 | E23: =C23*D23 -> 10638.698 | F23: =E23-600 -> 10038.698 | G23: Applied to HCG FY25 EBITDA
B24: Peer Median FY27E EV/EBITDA | C24: =J17 -> 17.904316 | D24: 555 | E24: =C24*D24 -> 9936.8952 | F24: =E24-600 -> 9336.8952 | G24: Applied to HCG FY27E EBITDA
B25: 75th percentile (specialty premium) | C25: =I17*1.1 -> 30.796231 | D25: 380 | E25: =C25*D25 -> 11702.568 | F25: =E25-600 -> 11102.568 | G25: Premium for specialty oncology asset
B26: Implied Avg Valuation | E26: =AVERAGE(E23:E25) -> 10759.387 | F26: =AVERAGE(F23:F25) -> 10159.387 | G26: Average of three methods

Sheet Precedents
B2: Precedent Transactions — Indian Healthcare M&A
B3: Source: VCCircle, Mergermarket, IFR, S&P CapIQ — last 36 months | All values ₹ Cr unless noted
B5: Date | C5: Target | D5: Acquirer | E5: Stake | F5: EV (₹ Cr) | G5: LTM Rev | H5: LTM EBITDA | I5: EV/EBITDA
B6: Apr-24 | C6: Care Hospitals (TPG) | D6: Blackstone | E6: 73% | F6: 6600 | G6: 1700 | H6: 280 | I6: 23.6
B7: Mar-24 | C7: Quality Care India | D7: Aster DM (India) | E7: 100% | F7: 8500 | G7: 1580 | H7: 365 | I7: 23.3
B8: Feb-24 | C8: Sahara Hospital (Lucknow) | D8: Max Healthcare | E8: 100% | F8: 940 | G8: 250 | H8: 60 | I8: 15.7
B9: Sep-23 | C9: Hexagon (Vijaya Diag.) | D9: KKR | E9: Increase | F9: 5650 | G9: 1350 | H9: 410 | I9: 13.8
B10: Aug-23 | C10: AMRI Hospitals | D10: Manipal | E10: 84% | F10: 2300 | G10: 720 | H10: 100 | I10: 23
B11: Jul-23 | C11: Asian Heart Institute | D11: Manipal (50%) | E11: 50% | F11: 1300 | G11: 380 | H11: 90 | I11: 14.4
B12: Mar-23 | C12: Medica Synergie | D12: Manipal | E12: 100% | F12: 1000 | G12: 480 | H12: 65 | I12: 15.4
B13: Dec-22 | C13: KIMS Hospitals (residual) | D13: General Atlantic exit | E13: Block | F13: 2100 | G13: 1450 | H13: 320 | I13: 6.6
B14: Sep-22 | C14: Healthcare Global (HCG) | D14: KKR | E14: Increase to 76% | F14: 6500 | G14: 1380 | H14: 230 | I14: 28.3
B15: Apr-22 | C15: Manipal Hospitals | D15: Temasek | E15: 59% | F15: 30000 | G15: 5400 | H15: 1000 | I15: 30
B17: Mean | I17: =AVERAGE(I6:I15) -> 19.41
B18: Median | I18: =MEDIAN(I6:I15) -> 19.35
B19: 75th %ile | I19: =PERCENTILE(I6:I15,0.75) -> 23.525
B21: Triangulation: HCG entry at 22.4x is consistent with specialty healthcare control premium precedents (Care 23.6x, Quality Care 23.3x, AMRI 23.0x). Lower than top-tier multi-specialty (Manipal/Temasek 30x) but premium to multi-specialty regional plays (Sahara 15.7x). The 22.4x reflects: (i) 76% control premium, (ii) scarcity of national oncology platforms, (iii) FY27E roll-forward implies 18.0x — converging to peers.

Sheet Sensitivity
B2: Sensitivity Analysis — Sponsor IRR & MOIC
B4: TABLE 1: IRR — Exit Multiple × Synergy Realization
C5: % of Base-Case Synergies Realized
B6: Exit Multiple ↓ | C6: 50% | D6: 75% | E6: 100% | F6: 125% | G6: 150%
B7: 14.0x | C7: 0.09 | D7: 0.124 | E7: 0.15 | F7: 0.174 | G7: 0.196
B8: 16.0x | C8: 0.13 | D8: 0.166 | E8: 0.193 | F8: 0.218 | G8: 0.241
B9: 18.0x | C9: 0.166 | D9: 0.204 | E9: 0.232 | F9: 0.258 | G9: 0.282
B10: 20.0x | C10: 0.199 | D10: 0.238 | E10: 0.268 | F10: 0.295 | G10: 0.319
B11: 22.0x | C11: 0.229 | D11: 0.27 | E11: 0.3 | F11: 0.327 | G11: 0.353
B13: Bold cell = Base Case (18.0x exit, 100% synergy realization). Min IRR for approval gate: 18%.
B15: TABLE 2: MOIC — Exit Multiple × Hold Period
C16: Hold Period (Years)
B17: Exit Multiple ↓ | C17: 3 yrs | D17: 4 yrs | E17: 5 yrs | F17: 6 yrs | G17: 7 yrs
B18: 14.0x | C18: 1.55 | D18: 1.8 | E18: 2.1 | F18: 2.42 | G18: 2.78
B19: 16.0x | C19: 2 | D19: 2.35 | E19: 2.75 | F19: 3.18 | G19: 3.65
B20: 18.0x | C20: 2.5 | D20: 2.95 | E20: 3.45 | F20: 4 | G20: 4.6
B21: 20.0x | C21: 3 | D21: 3.55 | E21: 4.15 | F21: 4.82 | G21: 5.55
B22: 22.0x | C22: 3.5 | D22: 4.15 | E22: 4.85 | F22: 5.65 | G22: 6.5
B25: TABLE 3: IRR — Entry Multiple × Senior Leverage
C26: Senior Leverage (x FY25 EBITDA)
B27: Entry Multiple ↓ | C27: 7.0x | D27: 8.0x | E27: 9.0x | F27: 10.0x | G27: 11.0x
B28: 20.0x | C28: 0.296 | D28: 0.318 | E28: 0.339 | F28: 0.358 | G28: 0.376
B29: 21.0x | C29: 0.27 | D29: 0.292 | E29: 0.313 | F29: 0.331 | G29: 0.348
B30: 22.4x | C30: 0.232 | D30: 0.253 | E30: 0.273 | F30: 0.29 | G30: 0.305
B31: 24.0x | C31: 0.196 | D31: 0.215 | E31: 0.234 | F31: 0.25 | G31: 0.264
B32: 26.0x | C32: 0.158 | D32: 0.176 | E32: 0.193 | F32: 0.207 | G32: 0.219
B34: All sensitivities reflect 100% synergy realization at 5-yr hold. Combined Entry+Exit+Leverage stress (downside): 24x entry × 16x exit × 7x lev = ~13% IRR (below approval threshold). Base case is robust to ~150bps re-rating risk.
