Workbook

Sheet Assumptions
A1: Scaler B2G | Assumptions Dashboard (₹ Cr)
A2: Blue = input | Yellow = key driver | Orange = ties to a deck figure | Black = formula | Green text on P&L = link from this tab
A4: A. REVENUE BUILD — drives the entire model
B5: FY26 | C5: FY27 | D5: FY28 | E5: FY29 | F5: FY30 | G5: Source / Note
A6: Central Government Schemes (PMKVY 5.0, MeitY) | B6: 0.84 | C6: 2.5 | D6: 6.5 | E6: 14 | F6: 25 | G6: 1 contract Q3 FY26 → 8 contracts FY30 at ₹15-19K/candidate
A7: PSU Upskilling (anchor segment) | B7: 0.86 | C7: 6 | D7: 14.5 | E7: 28.5 | F7: 47 | G7: 2 PSU clients FY26 → 18 PSU clients FY30 at ₹35-55K/employee
A8: State Government Missions | B8: 0 | C8: 0.7 | D8: 2.5 | E8: 4.5 | F8: 9 | G8: Enter FY27 only; 1 → 5 state contracts; lower margin tier
A9: University Partnerships | B9: 0.3 | C9: 1.3 | D9: 2.5 | E9: 5 | F9: 12 | G9: 1 partner FY26 → 18 partners FY30; curriculum IP licensing
A10: TOTAL REVENUE | B10: =SUM(B6:B9) -> 2 | C10: =SUM(C6:C9) -> 10.5 | D10: =SUM(D6:D9) -> 26 | E10: =SUM(E6:E9) -> 52 | F10: =SUM(F6:F9) -> 93 | G10: Deck Slide 10/12: FY26=₹2 FY28=₹26 FY30=₹93
A11: YoY Revenue Growth | C11: =(C10/B10)-1 -> 4.25 | D11: =(D10/C10)-1 -> 1.4761905 | E11: =(E10/D10)-1 -> 1 | F11: =(F10/E10)-1 -> 0.78846154
A12: FY26–FY30 CAGR | F12: =(F10/B10)^(1/4)-1 -> 1.6113389 | G12: Deck Slide 10: 5-yr CAGR 160%+
A14: B. GROSS MARGINS BY SEGMENT
A15: Central Govt Gross Margin | B15: 0.58 | G15: Deck Slide 9: 58% (after delivery + content)
A16: PSU Gross Margin | B16: 0.65 | G16: Deck Slide 9: 65% (anchor; enterprise-like delivery)
A17: State Govt Gross Margin | B17: 0.46 | G17: Deck Slide 9: 46% (high compliance overhead)
A18: University Gross Margin | B18: 0.72 | G18: Deck Slide 9: 72% (curriculum IP licensing)
A20: C. HEADCOUNT & PEOPLE COST
B21: FY26 | C21: FY27 | D21: FY28 | E21: FY29 | F21: FY30 | G21: Source / Note
A22: Total Headcount (FTEs) | B22: 11 | C22: 18 | D22: 30 | E22: 40 | F22: 50 | G22: Deck Slide 12: 11 FTEs FY26 → 30 FTEs FY28
A23: Avg Annual CTC per FTE (₹ Cr) | B23: 0.18 | C23: 0.2 | D23: 0.22 | E23: 0.24 | F23: 0.26 | G23: Mix: VP ₹55L; BD Mgrs ₹25-32L; Delivery ₹16-22L; rises with seniority
A24: Total People Cost (₹ Cr) | B24: =B22*B23 -> 1.98 | C24: =C22*C23 -> 3.6 | D24: =D22*D23 -> 6.6 | E24: =E22*E23 -> 9.6 | F24: =F22*F23 -> 13 | G24: HC × CTC; this is the largest single OPEX line
A26: D. NON-PEOPLE OPERATING COSTS
B27: FY26 | C27: FY27 | D27: FY28 | E27: FY29 | F27: FY30 | G27: Source / Note
A28: Technology / Platform Allocation | B28: 0.4 | C28: 0.55 | D28: 0.75 | E28: 1 | F28: 1.3 | G28: Share of Scaler platform cost allocated to B2G
A29: Legal, Compliance & Tender Costs | B29: 0.35 | C29: 0.45 | D29: 0.55 | E29: 0.7 | F29: 0.85 | G29: GeM, NCVET, audits, tender filings
A30: Travel & Business Development | B30: 0.25 | C30: 0.4 | D30: 0.55 | E30: 0.75 | F30: 0.95 | G30: Govt relationship building; PSU site visits
A31: Content Development (Y1 one-time + 4% rev refresh) | B31: 1.5 | C31: 0.3 | D31: 0.5 | E31: 0.8 | F31: 1.2 | G31: Y1: ₹1.5 Cr curriculum adaptation; Y2+ 4% of revenue
A32: G&A Allocation (% of revenue) | B32: 0.06 | C32: 0.06 | D32: 0.06 | E32: 0.06 | F32: 0.06 | G32: Shared services from Scaler parent (computed in P&L)
A33: Channel Partner & Govt Liaison Fees (% of revenue) | B33: 0 | C33: 0.04 | D33: 0.05 | E33: 0.07 | F33: 0.095 | G33: Govt sub-contractor + advisor commissions; scales with deal size
A35: E. CAPEX, FUNDING & VALUATION
A36: Setup Capex FY26 (one-time) | B36: 0.6 | G36: GeM, CPPP, NCVET portal setup; office systems
A37: Annual Maintenance Capex (FY27+) | B37: 0.2 | G37: Run-rate maintenance
A38: Scaler Parent Capital Injection — FY26 | B38: 2.5 | G38: Tranche 1: bridge to Y1 cash burn
A39: Scaler Parent Capital Injection — FY27 | B39: 0.7 | G39: Tranche 2: support Y2 working capital
A40: Scaler Parent Capital Injection — FY28 | B40: 0.3 | G40: Tranche 3: final tranche
A41: TOTAL SEED CAPITAL (FY26 + FY27 + FY28) | B41: =B38+B39+B40 -> 3.5 | G41: Deck Slide 2/10/11: ₹3.5 Cr seed ask
A43: WACC / Discount Rate | B43: 0.18 | G43: Ed-tech new vertical; execution + policy risk
A44: Terminal Growth Rate | B44: 0.05 | G44: Post-FY30 steady state
A45: EV/Revenue Multiple (median comps) | B45: 3.9 | G45: NIIT, TCS iON, TeamLease blended median
A46: EV/EBITDA Multiple (median comps) | B46: 19.5 | G46: Median across 6 ed-tech comps
...

Sheet P&L
A1: Scaler B2G | P&L + Cash Flow Summary (₹ Cr)
A2: All revenue & cost lines link from Assumptions tab. Change blue cells there → P&L updates here.
B4: FY26 | C4: FY27 | D4: FY28 | E4: FY29 | F4: FY30 | G4: FY26-30 CAGR
A5: REVENUE (linked from Assumptions tab)
A6: Central Government Schemes | B6: =Assumptions!B6 -> 0.84 | C6: =Assumptions!C6 -> 2.5 | D6: =Assumptions!D6 -> 6.5 | E6: =Assumptions!E6 -> 14 | F6: =Assumptions!F6 -> 25
A7: PSU Upskilling | B7: =Assumptions!B7 -> 0.86 | C7: =Assumptions!C7 -> 6 | D7: =Assumptions!D7 -> 14.5 | E7: =Assumptions!E7 -> 28.5 | F7: =Assumptions!F7 -> 47
A8: State Government Missions | B8: =Assumptions!B8 -> 0 | C8: =Assumptions!C8 -> 0.7 | D8: =Assumptions!D8 -> 2.5 | E8: =Assumptions!E8 -> 4.5 | F8: =Assumptions!F8 -> 9
A9: University Partnerships | B9: =Assumptions!B9 -> 0.3 | C9: =Assumptions!C9 -> 1.3 | D9: =Assumptions!D9 -> 2.5 | E9: =Assumptions!E9 -> 5 | F9: =Assumptions!F9 -> 12
A10: TOTAL REVENUE | B10: =SUM(B6:B9) -> 2 | C10: =SUM(C6:C9) -> 10.5 | D10: =SUM(D6:D9) -> 26 | E10: =SUM(E6:E9) -> 52 | F10: =SUM(F6:F9) -> 93 | G10: =(F10/B10)^(1/4)-1 -> 1.6113389
A11: YoY Growth | C11: =(C10/B10)-1 -> 4.25 | D11: =(D10/C10)-1 -> 1.4761905 | E11: =(E10/D10)-1 -> 1 | F11: =(F10/E10)-1 -> 0.78846154
A13: GROSS PROFIT = Σ (segment revenue × segment GM)
A14: Less: Direct Delivery Cost | B14: =B6*(1-Assumptions!B15)+B7*(1-Assumptions!B16)+B8*(1-Assumptions!B17)+B9*(1-Assumptions!B18) -> 0.7378 | C14: =C6*(1-Assumptions!B15)+C7*(1-Assumptions!B16)+C8*(1-Assumptions!B17)+C9*(1-Assumptions!B18) -> 3.892 | D14: =D6*(1-Assumptions!B15)+D7*(1-Assumptions!B16)+D8*(1-Assumptions!B17)+D9*(1-Assumptions!B18) -> 9.855 | E14: =E6*(1-Assumptions!B15)+E7*(1-Assumptions!B16)+E8*(1-Assumptions!B17)+E9*(1-Assumptions!B18) -> 19.685 | F14: =F6*(1-Assumptions!B15)+F7*(1-Assumptions!B16)+F8*(1-Assumptions!B17)+F9*(1-Assumptions!B18) -> 35.17
A15: GROSS PROFIT | B15: =B10-B14 -> 1.2622 | C15: =C10-C14 -> 6.608 | D15: =D10-D14 -> 16.145 | E15: =E10-E14 -> 32.315 | F15: =F10-F14 -> 57.83 | G15: =(F15/B15)^(1/4)-1 -> 1.6016942
A16: Blended Gross Margin | B16: =B15/B10 -> 0.6311 | C16: =C15/C10 -> 0.62933333 | D16: =D15/D10 -> 0.62096154 | E16: =E15/E10 -> 0.62144231 | F16: =F15/F10 -> 0.62182796
A18: OPERATING EXPENSES (linked from Assumptions)
A19: People Cost (HC × CTC) | B19: =Assumptions!B24 -> 1.98 | C19: =Assumptions!C24 -> 3.6 | D19: =Assumptions!D24 -> 6.6 | E19: =Assumptions!E24 -> 9.6 | F19: =Assumptions!F24 -> 13
A20: Technology / Platform | B20: =Assumptions!B28 -> 0.4 | C20: =Assumptions!C28 -> 0.55 | D20: =Assumptions!D28 -> 0.75 | E20: =Assumptions!E28 -> 1 | F20: =Assumptions!F28 -> 1.3
A21: Legal, Compliance & Tender | B21: =Assumptions!B29 -> 0.35 | C21: =Assumptions!C29 -> 0.45 | D21: =Assumptions!D29 -> 0.55 | E21: =Assumptions!E29 -> 0.7 | F21: =Assumptions!F29 -> 0.85
A22: Travel & Business Development | B22: =Assumptions!B30 -> 0.25 | C22: =Assumptions!C30 -> 0.4 | D22: =Assumptions!D30 -> 0.55 | E22: =Assumptions!E30 -> 0.75 | F22: =Assumptions!F30 -> 0.95
A23: Content Development | B23: =Assumptions!B31 -> 1.5 | C23: =Assumptions!C31 -> 0.3 | D23: =Assumptions!D31 -> 0.5 | E23: =Assumptions!E31 -> 0.8 | F23: =Assumptions!F31 -> 1.2
A24: General & Administrative (6% of revenue) | B24: =B10*Assumptions!B32 -> 0.12 | C24: =C10*Assumptions!C32 -> 0.63 | D24: =D10*Assumptions!D32 -> 1.56 | E24: =E10*Assumptions!E32 -> 3.12 | F24: =F10*Assumptions!F32 -> 5.58
A25: Channel Partner & Govt Liaison Fees | B25: =B10*Assumptions!B33 -> 0 | C25: =C10*Assumptions!C33 -> 0.42 | D25: =D10*Assumptions!D33 -> 1.3 | E25: =E10*Assumptions!E33 -> 3.64 | F25: =F10*Assumptions!F33 -> 8.835
A26: TOTAL OPEX | B26: =B19+B20+B21+B22+B23+B24+B25 -> 4.6 | C26: =C19+C20+C21+C22+C23+C24+C25 -> 6.35 | D26: =D19+D20+D21+D22+D23+D24+D25 -> 11.81 | E26: =E19+E20+E21+E22+E23+E24+E25 -> 19.61 | F26: =F19+F20+F21+F22+F23+F24+F25 -> 31.715
A27: Opex as % of Revenue | B27: =B26/B10 -> 2.3 | C27: =C26/C10 -> 0.6047619 | D27: =D26/D10 -> 0.45423077 | E27: =E26/E10 -> 0.37711538 | F27: =F26/F10 -> 0.34102151
A29: EBITDA (Deck Slide 10: positive FY27 onwards; FY30 = 28% margin)
A30: EBITDA | B30: =B15-B26 -> -3.3378 | C30: =C15-C26 -> 0.258 | D30: =D15-D26 -> 4.335 | E30: =E15-E26 -> 12.705 | F30: =F15-F26 -> 26.115
A31: EBITDA Margin | B31: =B30/B10 -> -1.6689 | C31: =C30/C10 -> 0.024571429 | D31: =D30/D10 -> 0.16673077 | E31: =E30/E10 -> 0.24432692 | F31: =F30/F10 -> 0.28080645
A32: Status | B32: =IF(B30>0,"+ EBITDA POSITIVE","- (loss)") -> - (loss) | C32: =IF(C30>0,"+ EBITDA POSITIVE","- (loss)") -> + EBITDA POSITIVE | D32: =IF(D30>0,"+ EBITDA POSITIVE","- (loss)") -> + EBITDA POSITIVE | E32: =IF(E30>0,"+ EBITDA POSITIVE","- (loss)") -> + EBITDA POSITIVE | F32: =IF(F30>0,"+ EBITDA POSITIVE","- (loss)") -> + EBITDA POSITIVE
A34: DEPRECIATION, TAX & NET PROFIT
A35: Less: Depreciation & Amortisation | B35: 0.2 | C35: 0.3 | D35: 0.27 | E35: 0.24 | F35: 0.21
A36: EBIT (Operating Profit) | B36: =B30-B35 -> -3.5378 | C36: =C30-C35 -> -0.042 | D36: =D30-D35 -> 4.065 | E36: =E30-E35 -> 12.465 | F36: =F30-F35 -> 25.905
A37: Less: Tax (25% on positive EBIT) | B37: =MAX(0,B36)*Assumptions!B47 -> 0 | C37: =MAX(0,C36)*Assumptions!B47 -> 0 | D37: =MAX(0,D36)*Assumptions!B47 -> 1.01625 | E37: =MAX(0,E36)*Assumptions!B47 -> 3.11625 | F37: =MAX(0,F36)*Assumptions!B47 -> 6.47625
A38: NET PROFIT (PAT) | B38: =B36-B37 -> -3.5378 | C38: =C36-C37 -> -0.042 | D38: =D36-D37 -> 3.04875 | E38: =E36-E37 -> 9.34875 | F38: =F36-F37 -> 19.42875
A40: CASH FLOW SUMMARY
A41: Less: Working Capital Increase (rev × 90 days × 30%) | B41: =B10*0.3*90/365 -> 0.14794521 | C41: =(C10-B10)*0.3*90/365 -> 0.62876712 | D41: =(D10-C10)*0.3*90/365 -> 1.1465753 | E41: =(E10-D10)*0.3*90/365 -> 1.9232877 | F41: =(F10-E10)*0.3*90/365 -> 3.0328767
A42: Operating Cash Flow | B42: =B30-B37-B41 -> -3.4857452 | C42: =C30-C37-C41 -> -0.37076712 | D42: =D30-D37-D41 -> 2.1721747 | E42: =E30-E37-E41 -> 7.6654623 | F42: =F30-F37-F41 -> 16.605873
A43: Less: Capex (Setup + Maintenance) | B43: =-Assumptions!B36 -> -0.6 | C43: =-Assumptions!B37 -> -0.2 | D43: =-Assumptions!B37 -> -0.2 | E43: =-Assumptions!B37 -> -0.2 | F43: =-Assumptions!B37 -> -0.2
A44: FREE CASH FLOW | B44: =B42+B43 -> -4.0857452 | C44: =C42+C43 -> -0.57076712 | D44: =D42+D43 -> 1.9721747 | E44: =E42+E43 -> 7.4654623 | F44: =F42+F43 -> 16.405873
A45: Add: Scaler Parent Capital Injection | B45: =Assumptions!B38 -> 2.5 | C45: =Assumptions!B39 -> 0.7 | D45: =Assumptions!B40 -> 0.3 | E45: 0 | F45: 0
A46: Net Change in Cash | B46: =B44+B45 -> -1.5857452 | C46: =C44+C45 -> 0.12923288 | D46: =D44+D45 -> 2.2721747 | E46: =E44+E45 -> 7.4654623 | F46: =F44+F45 -> 16.405873
...

Sheet Valuation
A1: Scaler B2G | Valuation — DCF + Comparable Multiples (₹ Cr)
A2: Deck Slide 10 says ₹360 Cr Implied EV at 3.9x median revenue. DCF is the floor (conservative); comps are the realistic exit value.
A4: DCF VALUATION (Discount Rate from Assumptions tab)
B5: FY26 | C5: FY27 | D5: FY28 | E5: FY29 | F5: FY30
A6: Free Cash Flow (from P&L) | B6: ='P&L'!B44 -> -4.0857452 | C6: ='P&L'!C44 -> -0.57076712 | D6: ='P&L'!D44 -> 1.9721747 | E6: ='P&L'!E44 -> 7.4654623 | F6: ='P&L'!F44 -> 16.405873
A7: Discount Factor | B7: =1/(1+Assumptions!B43)^1 -> 0.84745763 | C7: =1/(1+Assumptions!B43)^2 -> 0.71818443 | D7: =1/(1+Assumptions!B43)^3 -> 0.60863087 | E7: =1/(1+Assumptions!B43)^4 -> 0.51578888 | F7: =1/(1+Assumptions!B43)^5 -> 0.43710922
A8: PV of FCF | B8: =B6*B7 -> -3.4624959 | C8: =C6*C7 -> -0.40991606 | D8: =D6*D7 -> 1.2003264 | E8: =E6*E7 -> 3.8506024 | F8: =F6*F7 -> 7.1711584
A10: Sum of PV(FCF), FY26-FY30 | B10: =SUM(B8:F8) -> 8.3496752
A11: Terminal EBITDA (FY30) | B11: ='P&L'!F30 -> 26.115
A12: Terminal Value = FY30 EBITDA × (1+g) / (WACC − g) | B12: =B11*(1+Assumptions!B44)/(Assumptions!B43-Assumptions!B44) -> 210.92885
A13: PV of Terminal Value | B13: =B12*F7 -> 92.198943
A14: ENTERPRISE VALUE — DCF | B14: =B10+B13 -> 100.54862 | G14: Conservative floor
A16: COMPARABLE COMPANY ANALYSIS
A17: Company | B17: EV (₹ Cr) | C17: Revenue (₹ Cr) | D17: EV/Revenue | E17: EBITDA (₹ Cr) | F17: EV/EBITDA | G17: Notes
A18: NIIT Ltd (Govt segment) | B18: 1200 | C18: 320 | D18: 3.8x | E18: 64 | F18: 18.8x | G18: NSE listed; segment data
A19: TCS iON (estimate) | B19: 4500 | C19: 900 | D19: 5.0x | E19: 270 | F19: 16.7x | G19: Unlisted; TCS Annual Report
A20: Simplilearn (Series F) | B20: 2200 | C20: 550 | D20: 4.0x | E20: 88 | F20: 25.0x | G20: 2023 valuation
A21: Coursera Govt segment | B21: 3100 | C21: 620 | D21: 5.0x | E21: 93 | F21: 33.3x | G21: US-focused; premium
A22: TeamLease Skills | B22: 750 | C22: 250 | D22: 3.0x | E22: 37 | F22: 20.3x | G22: NSE listed
A23: IL&FS / Learnet | B23: 180 | C23: 90 | D23: 2.0x | E23: 12 | F23: 15.0x | G23: Distressed; floor
A24: MEDIAN | B24: =MEDIAN(B18:B23) -> 1700 | C24: =MEDIAN(C18:C23) -> 435 | D24: 3.9 | E24: =MEDIAN(E18:E23) -> 76 | F24: 19.5 | G24: Used for Scaler valuation
A26: IMPLIED VALUATION FOR SCALER B2G (FY30 metrics × comp multiples)
A27: Basis | B27: Multiple | C27: Metric (₹ Cr) | D27: Implied EV (₹ Cr)
A28: EV/Revenue @ 3.9x (median comp) × FY30 Revenue | B28: =Assumptions!B45 -> 3.9 | C28: ='P&L'!F10 -> 93 | D28: =B28*C28 -> 362.7 | G28: Deck Slide 10: ₹360 Cr
A29: EV/EBITDA @ 19.5x (median comp) × FY30 EBITDA | B29: =Assumptions!B46 -> 19.5 | C29: ='P&L'!F30 -> 26.115 | D29: =B29*C29 -> 509.2425
A30: DCF Valuation (WACC 18%, Terminal Growth 5%) | B30: — | C30: — | D30: =B14 -> 100.54862
A32: TRIANGULATION — three independent valuation approaches
A33: DCF (floor) vs EV/Revenue (median) vs EV/EBITDA (median)
A34: Average of 3 methods | B34: =AVERAGE(D28:D30) -> 324.16371 | G34: Triangulated EV — most defensible single number
