Workbook

Sheet Summary
A1: Solar Plant Investment — One-Page Summary
A2: Hypothetical 10 MW utility-scale solar IPP in India under 25-yr PPA. 30/70 equity-debt.
A4: DEAL TERMS
A5: Plant capacity | B5: =Assumptions!$B$5 -> 10 | C5: MW
A6: Total capex | B6: =Assumptions!$B$7 -> 37.5 | C6: ₹ crore
A7: Equity ticket | B7: =Assumptions!$B$9 -> 11.25 | C7: ₹ crore
A8: Debt | B8: =Assumptions!$B$10 -> 26.25 | C8: ₹ crore
A9: PPA tariff | B9: =Assumptions!$B$14 -> 2.8 | C9: ₹/kWh
A10: CUF Year 1 | B10: =Assumptions!$B$15 -> 0.22 | C10: %
A11: Debt cost | B11: =Assumptions!$B$11 -> 0.09 | C11: %
A12: Debt tenor | B12: =Assumptions!$B$12 -> 15 | C12: years
A13: Project life | B13: =Assumptions!$B$20 -> 25 | C13: years
A15: BASE CASE EQUITY IRR (25-year, levered)
A16: Equity IRR | B16: =Scenarios!$E$16 -> 0.10892419
A18: RISK SCENARIOS — EQUITY IRR
A19: Base case | B19: =Scenarios!$E$16 -> 0.10892419 | C19: Current sourced 2025-26 inputs
A20: Tariff haircut 10% | B20: =Scenarios!$E$17 -> 0.07648756 | C20: DISCOM payment delays / curtailment
A21: CUF drops to 18% | B21: =Scenarios!$E$18 -> 0.050425888 | C21: Curtailment / weather / actual industry CUF
A22: Capex overrun 15% | B22: =Scenarios!$E$19 -> 0.073208318 | C22: Commissioning delays / cost inflation
A23: Combined downside | B23: =Scenarios!$E$20 -> -0.0033212509 | C23: All three above — equity gets thin
A24: Upside (CUF 25%, ₹3.0/kWh) | B24: =Scenarios!$E$21 -> 0.18271537 | C24: Best execution / well-sited
A26: VIEW
A27: Base case equity IRR sits at the LOWER END of the 12-15% infra equity hurdle. Cash flows are underwritten by
A28: a 25-yr fixed-tariff PPA, but the IRR is sensitive: stress tests drop returns by 350-600 bps; combined downside
A29: wipes the equity. Indian solar tariffs have crashed from ₹5+ in 2014 to ₹2.50-2.86 today (SECI 2025 auctions),
A30: while capex per MW has fallen more slowly. The economics are structurally tight, not a modeling artifact.
A32: IMPLICATION FOR UC IMPOWER:
A33: A $2.5-3.5M equity cheque into a single solar IPP is marginal in base case; downside is binary.
A34: The interesting climate plays are upstream:
A35: (a) Developer / platform scaling 50+ assets — captures dev margin + platform exit multiple
A36: (b) Enabling technology — battery storage (AmpereHour in your portfolio), grid software, EV-tech
A37: (c) NBFCs lending to developers — bank-spread + fee economics, not asset IRR
A39: AmpereHour sits in (b) — exactly the layer to capture climate exposure without IPP returns compression.

Sheet Assumptions
A1: Assumptions — All inputs sourced from 2025-26 public benchmarks
A2: Blue = input (editable). Green = calculated. Edit any blue cell to flow through the entire model.
A4: Input | B4: Value | C4: Unit | D4: Source / Benchmark
A5: Plant capacity | B5: 10 | C5: MW | D5: Illustrative mid-scale plant
A6: Capex per MW | B6: 3.75 | C6: ₹ cr/MW | D6: klkindia Nov 2025: ₹3.75–4.25 cr/MW; utility-scale developers achieve lower end
A7: Total capex | B7: =Assumptions!$B$5*Assumptions!$B$6 -> 37.5 | C7: ₹ cr | D7: Calc: capacity × capex/MW
A8: Equity % | B8: 0.3 | C8: % | D8: Given in interview brief
A9: Equity (₹) | B9: =Assumptions!$B$8*Assumptions!$B$7 -> 11.25 | C9: ₹ cr | D9: Calc: equity % × capex
A10: Debt (₹) | B10: =(1-Assumptions!$B$8)*Assumptions!$B$7 -> 26.25 | C10: ₹ cr | D10: Calc: 70% × capex
A11: Interest rate | B11: 0.09 | C11: % | D11: BNEF 2025 survey: 8.5–9.75% greenfield solar; ACME Solar 2025 refi at 8.8%
A12: Debt tenor | B12: 15 | C12: years | D12: Industry standard PF tenor; ACME refi was 18-20 yrs
A13: Annual debt service | B13: =-PMT(Assumptions!$B$11,Assumptions!$B$12,Assumptions!$B$10) -> 3.2565457 | C13: ₹ cr | D13: Calc: annuity payment
A14: PPA tariff | B14: 2.8 | C14: ₹/kWh | D14: SECI Oct 2025: record ₹2.86; ACME 25-yr PPA ₹3.05; BNC Apr 2026 ₹2.60; midpoint ₹2.80
A15: CUF Year 1 | B15: 0.22 | C15: % | D15: PPA-level AC CUF 22-25% typical with DC overloading (ScienceDirect 2024); CERC AC benchmark 19%
A16: Annual degradation | B16: 0.005 | C16: % | D16: Standard panel mfr warranty range 0.4-0.7%/yr; 0.5% midpoint
A17: O&M Year 1 | B17: 0.5 | C17: ₹ cr | D17: ₹5 lakh/MW utility scale; klkindia ₹6-10 lakh range is 1 MW illustration (no scale economies)
A18: O&M escalation | B18: 0.05 | C18: % | D18: CPI-linked
A19: Tax rate | B19: 0.25 | C19: % | D19: Indian corporate, Section 115BAA (post-DDT)
A20: Project life | B20: 25 | C20: years | D20: Matches PPA tenor

Sheet Cash Flow
A1: 5-Year Cash Flow (₹ crore)
A2: Year 0 = construction (equity outflow). Years 1-5 = operations under 25-yr PPA. IRR computed over full 25-year life — see Scenarios tab.
A4: Line item | B4: Year 0 | C4: Year 1 | D4: Year 2 | E4: Year 3 | F4: Year 4 | G4: Year 5
A5: PHYSICAL OPERATIONS
A6: Generation (million kWh) | B6: =0 -> 0 | C6: =Assumptions!$B$5*8760*Assumptions!$B$15*(1-Assumptions!$B$16)^(1-1)/1000 -> 19.272 | D6: =Assumptions!$B$5*8760*Assumptions!$B$15*(1-Assumptions!$B$16)^(2-1)/1000 -> 19.17564 | E6: =Assumptions!$B$5*8760*Assumptions!$B$15*(1-Assumptions!$B$16)^(3-1)/1000 -> 19.079762 | F6: =Assumptions!$B$5*8760*Assumptions!$B$15*(1-Assumptions!$B$16)^(4-1)/1000 -> 18.984363 | G6: =Assumptions!$B$5*8760*Assumptions!$B$15*(1-Assumptions!$B$16)^(5-1)/1000 -> 18.889441
A8: P&L (₹ crore)
A9: Revenue | B9: =0 -> 0 | C9: =C6*Assumptions!$B$14/10 -> 5.39616 | D9: =D6*Assumptions!$B$14/10 -> 5.3691792 | E9: =E6*Assumptions!$B$14/10 -> 5.3423333 | F9: =F6*Assumptions!$B$14/10 -> 5.3156216 | G9: =G6*Assumptions!$B$14/10 -> 5.2890435
A10: (–) O&M cost | B10: =0 -> 0 | C10: =-Assumptions!$B$17*(1+Assumptions!$B$18)^(1-1) -> -0.5 | D10: =-Assumptions!$B$17*(1+Assumptions!$B$18)^(2-1) -> -0.525 | E10: =-Assumptions!$B$17*(1+Assumptions!$B$18)^(3-1) -> -0.55125 | F10: =-Assumptions!$B$17*(1+Assumptions!$B$18)^(4-1) -> -0.5788125 | G10: =-Assumptions!$B$17*(1+Assumptions!$B$18)^(5-1) -> -0.60775313
A11: EBITDA | B11: =0 -> 0 | C11: =C9+C10 -> 4.89616 | D11: =D9+D10 -> 4.8441792 | E11: =E9+E10 -> 4.7910833 | F11: =F9+F10 -> 4.7368091 | G11: =G9+G10 -> 4.6812904
A12: (–) Depreciation | B12: =0 -> 0 | C12: =-Assumptions!$B$7/Assumptions!$B$20 -> -1.5 | D12: =-Assumptions!$B$7/Assumptions!$B$20 -> -1.5 | E12: =-Assumptions!$B$7/Assumptions!$B$20 -> -1.5 | F12: =-Assumptions!$B$7/Assumptions!$B$20 -> -1.5 | G12: =-Assumptions!$B$7/Assumptions!$B$20 -> -1.5
A13: EBIT | B13: =0 -> 0 | C13: =C11+C12 -> 3.39616 | D13: =D11+D12 -> 3.3441792 | E13: =E11+E12 -> 3.2910833 | F13: =F11+F12 -> 3.2368091 | G13: =G11+G12 -> 3.1812904
A15: DEBT SCHEDULE (₹ crore)
A16: (–) Interest expense | B16: =0 -> 0 | C16: =IPMT(Assumptions!$B$11,1,Assumptions!$B$12,Assumptions!$B$10) -> -2.3625 | D16: =IPMT(Assumptions!$B$11,2,Assumptions!$B$12,Assumptions!$B$10) -> -2.2820359 | E16: =IPMT(Assumptions!$B$11,3,Assumptions!$B$12,Assumptions!$B$10) -> -2.19433 | F16: =IPMT(Assumptions!$B$11,4,Assumptions!$B$12,Assumptions!$B$10) -> -2.0987306 | G16: =IPMT(Assumptions!$B$11,5,Assumptions!$B$12,Assumptions!$B$10) -> -1.9945272
A17: (–) Principal repayment | B17: =0 -> 0 | C17: =PPMT(Assumptions!$B$11,1,Assumptions!$B$12,Assumptions!$B$10) -> -0.89404567 | D17: =PPMT(Assumptions!$B$11,2,Assumptions!$B$12,Assumptions!$B$10) -> -0.97450978 | E17: =PPMT(Assumptions!$B$11,3,Assumptions!$B$12,Assumptions!$B$10) -> -1.0622157 | F17: =PPMT(Assumptions!$B$11,4,Assumptions!$B$12,Assumptions!$B$10) -> -1.1578151 | G17: =PPMT(Assumptions!$B$11,5,Assumptions!$B$12,Assumptions!$B$10) -> -1.2620184
A19: EQUITY CASH FLOW (₹ crore)
A20: PBT (EBIT + Interest) | B20: =0 -> 0 | C20: =C13+C16 -> 1.03366 | D20: =D13+D16 -> 1.0621433 | E20: =E13+E16 -> 1.0967533 | F20: =F13+F16 -> 1.1380785 | G20: =G13+G16 -> 1.1867632
A21: (–) Tax | B21: =0 -> 0 | C21: =-MAX(0,C20)*Assumptions!$B$19 -> -0.258415 | D21: =-MAX(0,D20)*Assumptions!$B$19 -> -0.26553583 | E21: =-MAX(0,E20)*Assumptions!$B$19 -> -0.27418832 | F21: =-MAX(0,F20)*Assumptions!$B$19 -> -0.28451963 | G21: =-MAX(0,G20)*Assumptions!$B$19 -> -0.29669079
A22: PAT | B22: =0 -> 0 | C22: =C20+C21 -> 0.775245 | D22: =D20+D21 -> 0.79660748 | E22: =E20+E21 -> 0.82256497 | F22: =F20+F21 -> 0.8535589 | G22: =G20+G21 -> 0.89007237
A23: Free Cash Flow to Equity | B23: =-Assumptions!$B$9 -> -11.25 | C23: =C22-C12+C17 -> 1.3811993 | D23: =D22-D12+D17 -> 1.3220977 | E23: =E22-E12+E17 -> 1.2603493 | F23: =F22-F12+F17 -> 1.1957438 | G23: =G22-G12+G17 -> 1.1280539
A25: Note: 25-year equity IRR is calculated on the Scenarios tab using the same logic extended over the full PPA tenor.
A26: A 5-year IRR alone is misleading — equity capex is not yet recovered in Year 5.

Sheet Scenarios
A1: Scenarios & Risk Analysis
A2: Equity IRR computed over the full 25-yr PPA. The yellow cells in the scenario table are the inputs that change per scenario; the helper area below extends each scenario over 25 years.
A4: KEY RISKS FOR A SOLAR IPP IN INDIA
A5: Risk | B5: Description
A6: Tariff / DISCOM counterparty | B6: PPA fixed 25 yrs but DISCOM payment delays routine (esp. TN, AP); curtailment in oversupplied grids
A7: Generation (CUF) | B7: Weather variability, panel underperformance, curtailment can drop CUF 1-3 ppts vs design
A8: Capex overrun / commissioning delay | B8: Land, evacuation infra, equipment delays — IRR erodes if commissioning slips
A9: Module degradation > expected | B9: Cheap modules degrade above 0.5%/yr warranty; long-tail revenue erosion
A10: Refinancing / interest rate | B10: Long-tenor exposure to rate cycles; floating-rate debt amplifies this
A11: Regulatory / land / ESG | B11: Policy shifts, RPO enforcement, land disputes, biodiversity flags — UC Impower weighs these heavily
A14: SCENARIO ANALYSIS — equity IRR sensitivities
A15: Scenario | B15: CUF | C15: Tariff (₹/kWh) | D15: Capex mult. | E15: Equity IRR | F15: Risk captured
A16: Base case (current sourced inputs) | B16: 0.22 | C16: 2.8 | D16: 1 | E16: =IFERROR(IRR(B26:AA26),"<0% Loss") -> 0.10892419 | F16: Sourced 2025-26 inputs hold
A17: Tariff haircut 10% | B17: 0.22 | C17: 2.52 | D17: 1 | E17: =IFERROR(IRR(B27:AA27),"<0% Loss") -> 0.07648756 | F17: DISCOM payment delays / curtailment
A18: CUF drops to 18% | B18: 0.18 | C18: 2.8 | D18: 1 | E18: =IFERROR(IRR(B28:AA28),"<0% Loss") -> 0.050425888 | F18: Curtailment / weather / SBICAPS notes 16.5% actual
A19: Capex overrun 15% | B19: 0.22 | C19: 2.8 | D19: 1.15 | E19: =IFERROR(IRR(B29:AA29),"<0% Loss") -> 0.073208318 | F19: Commissioning delays / cost inflation
A20: Combined downside | B20: 0.18 | C20: 2.52 | D20: 1.15 | E20: =IFERROR(IRR(B30:AA30),"<0% Loss") -> -0.0033212509 | F20: All three risks materialize
A21: Upside (CUF 25%, ₹3.0) | B21: 0.25 | C21: 3 | D21: 1 | E21: =IFERROR(IRR(B31:AA31),"<0% Loss") -> 0.18271537 | F21: Best execution / well-sited
A24: Helper: 25-year FCFE per scenario (engine for IRR formulas above)
A25: Scenario | B25: Y0 | C25: Y1 | D25: Y2 | E25: Y3 | F25: Y4 | G25: Y5 | H25: Y6 | I25: Y7 | J25: Y8 | K25: Y9 | L25: Y10 | M25: Y11 | N25: Y12 | O25: Y13 | P25: Y14 | Q25: Y15 | R25: Y16 | S25: Y17 | T25: Y18 | U25: Y19 | V25: Y20 | W25: Y21 | X25: Y22 | Y25: Y23 | Z25: Y24 | AA25: Y25
A26: Base case (current sourced inputs) | B26: =-((Assumptions!$B$7*$D$16)*Assumptions!$B$8) -> -11.25 | C26: =(((((Assumptions!$B$5*8760*$B$16*(1-Assumptions!$B$16)^(1-1)/1000)*$C$16/10)+(-Assumptions!$B$17*(1+Assumptions!$B$18)^(1-1)))+IF(1<=Assumptions!$B$20,-(Assumptions!$B$7*$D$16)/Assumptions!$B$20,0)+IF(1<=Assumptions!$B$12,IPMT(Assumptions!$B$11,1,Assumptions!$B$12,((Assumptions!$B$7*$D$16)*(1-Assumptions!$B$8))),0))+(-MAX(0,((((Assumptions!$B$5*8760*$B$16*(1-Assumptions!$B$16)^(1-1)/1000)*$C$16/10)+(-Assumptions!$B$17*(1+Assumptions!$B$18)^(1-1)))+IF(1<=Assumptions!$B$20,-(Assumptions!$B$7*$D$16)/Assumptions!$B$20,0)+IF(1<=Assumptions!$B$12,IPMT(Assumptions!$B$11,1,Assumptions!$B$12,((Assumptions!$B$7*$D$16)*(1-Assumptions!$B$8))),0)))*Assumptions!$B$19))-(IF(1<=Assumptions!$B$20,-(Assumptions!$B$7*$D$16)/Assumptions!$B$20,0))+(IF(1<=Assumptions!$B$12,PPMT(Assumptions!$B$11,1,Assumptions!$B$12,((Assumptions!$B$7*$D$16)*(1-Assumptions!$B$8))),0)) -> 1.3811993 | D26: =(((((Assumptions!$B$5*8760*$B$16*(1-Assumptions!$B$16)^(2-1)/1000)*$C$16/10)+(-Assumptions!$B$17*(1+Assumptions!$B$18)^(2-1)))+IF(2<=Assumptions!$B$20,-(Assumptions!$B$7*$D$16)/Assumptions!$B$20,0)+IF(2<=Assumptions!$B$12,IPMT(Assumptions!$B$11,2,Assumptions!$B$12,((Assumptions!$B$7*$D$16)*(1-Assumptions!$B$8))),0))+(-MAX(0,((((Assumptions!$B$5*8760*$B$16*(1-Assumptions!$B$16)^(2-1)/1000)*$C$16/10)+(-Assumptions!$B$17*(1+Assumptions!$B$18)^(2-1)))+IF(2<=Assumptions!$B$20,-(Assumptions!$B$7*$D$16)/Assumptions!$B$20,0)+IF(2<=Assumptions!$B$12,IPMT(Assumptions!$B$11,2,Assumptions!$B$12,((Assumptions!$B$7*$D$16)*(1-Assumptions!$B$8))),0)))*Assumptions!$B$19))-(IF(2<=Assumptions!$B$20,-(Assumptions!$B$7*$D$16)/Assumptions!$B$20,0))+(IF(2<=Assumptions!$B$12,PPMT(Assumptions!$B$11,2,Assumptions!$B$12,((Assumptions!$B$7*$D$16)*(1-Assumptions!$B$8))),0)) -> 1.3220977 | E26: =(((((Assumptions!$B$5*8760*$B$16*(1-Assumptions!$B$16)^(3-1)/1000)*$C$16/10)+(-Assumptions!$B$17*(1+Assumptions!$B$18)^(3-1)))+IF(3<=Assumptions!$B$20,-(Assumptions!$B$7*$D$16)/Assumptions!$B$20,0)+IF(3<=Assumptions!$B$12,IPMT(Assumptions!$B$11,3,Assumptions!$B$12,((Assumptions!$B$7*$D$16)*(1-Assumptions!$B$8))),0))+(-MAX(0,((((Assumptions!$B$5*8760*$B$16*(1-Assumptions!$B$16)^(3-1)/1000)*$C$16/10)+(-Assumptions!$B$17*(1+Assumptions!$B$18)^(3-1)))+IF(3<=Assumptions!$B$20,-(Assumptions!$B$7*$D$16)/Assumptions!$B$20,0)+IF(3<=Assumptions!$B$12,IPMT(Assumptions!$B$11,3,Assumptions!$B$12,((Assumptions!$B$7*$D$16)*(1-Assumptions!$B$8))),0)))*Assumptions!$B$19))-(IF(3<=Assumptions!$B$20,-(Assumptions!$B$7*$D$16)/Assumptions!$B$20,0))+(IF(3<=Assumptions!$B$12,PPMT(Assumptions!$B$11,3,Assumptions!$B$12,((Assumptions!$B$7*$D$16)*(1-Assumptions!$B$8))),0)) -> 1.2603493 | F26: =(((((Assumptions!$B$5*8760*$B$16*(1-Assumptions!$B$16)^(4-1)/1000)*$C$16/10)+(-Assumptions!$B$17*(1+Assumptions!$B$18)^(4-1)))+IF(4<=Assumptions!$B$20,-(Assumptions!$B$7*$D$16)/Assumptions!$B$20,0)+IF(4<=Assumptions!$B$12,IPMT(Assumptions!$B$11,4,Assumptions!$B$12,((Assumptions!$B$7*$D$16)*(1-Assumptions!$B$8))),0))+(-MAX(0,((((Assumptions!$B$5*8760*$B$16*(1-Assumptions!$B$16)^(4-1)/1000)*$C$16/10)+(-Assumptions!$B$17*(1+Assumptions!$B$18)^(4-1)))+IF(4<=Assumptions!$B$20,-(Assumptions!$B$7*$D$16)/Assumptions!$B$20,0)+IF(4<=Assumptions!$B$12,IPMT(Assumptions!$B$11,4,Assumptions!$B$12,((Assumptions!$B$7*$D$16)*(1-Assumptions!$B$8))),0)))*Assumptions!$B$19))-(IF(4<=Assumptions!$B$20,-(Assumptions!$B$7*$D$16)/Assumptions!$B$20,0))+(IF(4<=Assumptions!$B$12,PPMT(Assumptions!$B$11,4,Assumptions!$B$12,((Assumptions!$B$7*$D$16)*(1-Assumptions!$B$8))),0)) -> 1.1957438 | G26: =(((((Assumptions!$B$5*8760*$B$16*(1-Assumptions!$B$16)^(5-1)/1000)*$C$16/10)+(-Assumptions!$B$17*(1+Assumptions!$B$18)^(5-1)))+IF(5<=Assumptions!$B$20,-(Assumptions!$B$7*$D$16)/Assumptions!$B$20,0)+IF(5<=Assumptions!$B$12,IPMT(Assumptions!$B$11,5,Assumptions!$B$12,((Assumptions!$B$7*$D$16)*(1-Assumptions!$B$8))),0))+(-MAX(0,((((Assumptions!$B$5*8760*$B$16*(1-Assumptions!$B$16)^(5-1)/1000)*$C$16/10)+(-Assumptions!$B$17*(1+Assumptions!$B$18)^(5-1)))+IF(5<=Assumptions!$B$20,-(Assumptions!$B$7*$D$16)/Assumptions!$B$20,0)+IF(5<=Assumptions!$B$12,IPMT(Assumptions!$B$11,5,Assumptions!$B$12,((Assumptions!$B$7*$D$16)*(1-Assumptions!$B$8))),0)))*Assumptions!$B$19))-(IF(5<=Assumptions!$B$20,-(Assumptions!$B$7*$D$16)/Assumptions!$B$20,0))+(IF(5<=Assumptions!$B$12,PPMT(Assumptions!$B$11,5,Assumptions!$B$12,((Assumptions!$B$7*$D$16)*(1-Assumptions!$B$8))),0)) -> 1.1280539 | H26: =(((((Assumptions!$B$5*8760*$B$16*(1-Assumptions!$B$16)^(6-1)/1000)*$C$16/10)+(-Assumptions!$B$17*(1+Assumptions!$B$18)^(6-1)))+IF(6<=Assumptions!$B$20,-(Assumptions!$B$7*$D$16)/Assumptions!$B$20,0)+IF(6<=Assumptions!$B$12,IPMT(Assumptions!$B$11,6,Assumptions!$B$12,((Assumptions!$B$7*$D$16)*(1-Assumptions!$B$8))),0))+(-MAX(0,((((Assumptions!$B$5*8760*$B$16*(1-Assumptions!$B$16)^(6-1)/1000)*$C$16/10)+(-Assumptions!$B$17*(1+Assumptions!$B$18)^(6-1)))+IF(6<=Assumptions!$B$20,-(Assumptions!$B$7*$D$16)/Assumptions!$B$20,0)+IF(6<=Assumptions!$B$12,IPMT(Assumptions!$B$11,6,Assumptions!$B$12,((Assumptions!$B$7*$D$16)*(1-Assumptions!$B$8))),0)))*Assumptions!$B$19))-(IF(6<=Assumptions!$B$20,-(Assumptions!$B$7*$D$16)/Assumptions!$B$20,0))+(IF(6<=Assumptions!$B$12,PPMT(Assumptions!$B$11,6,Assumptions!$B$12,((Assumptions!$B$7*$D$16)*(1-Assumptions!$B$8))),0)) -> 1.0570339 | I26: =(((((Assumptions!$B$5*8760*$B$16*(1-Assumptions!$B$16)^(7-1)/1000)*$C$16/10)+(-Assumptions!$B$17*(1+Assumptions!$B$18)^(7-1)))+IF(7<=Assumptions!$B$20,-(Assumptions!$B$7*$D$16)/Assumptions!$B$20,0)+IF(7<=Assumptions!$B$12,IPMT(Assumptions!$B$11,7,Assumptions!$B$12,((Assumptions!$B$7*$D$16)*(1-Assumptions!$B$8))),0))+(-MAX(0,((((Assumptions!$B$5*8760*$B$16*(1-Assumptions!$B$16)^(7-1)/1000)*$C$16/10)+(-Assumptions!$B$17*(1+Assumptions!$B$18)^(7-1)))+IF(7<=Assumptions!$B$20,-(Assumptions!$B$7*$D$16)/Assumptions!$B$20,0)+IF(7<=Assumptions!$B$12,IPMT(Assumptions!$B$11,7,Assumptions!$B$12,((Assumptions!$B$7*$D$16)*(1-Assumptions!$B$8))),0)))*Assumptions!$B$19))-(IF(7<=Assumptions!$B$20,-(Assumptions!$B$7*$D$16)/Assumptions!$B$20,0))+(IF(7<=Assumptions!$B$12,PPMT(Assumptions!$B$11,7,Assumptions!$B$12,((Assumptions!$B$7*$D$16)*(1-Assumptions!$B$8))),0)) -> 0.98241785 | J26: =(((((Assumptions!$B$5*8760*$B$16*(1-Assumptions!$B$16)^(8-1)/1000)*$C$16/10)+(-Assumptions!$B$17*(1+Assumptions!$B$18)^(8-1)))+IF(8<=Assumptions!$B$20,-(Assumptions!$B$7*$D$16)/Assumptions!$B$20,0)+IF(8<=Assumptions!$B$12,IPMT(Assumptions!$B$11,8,Assumptions!$B$12,((Assumptions!$B$7*$D$16)*(1-Assumptions!$B$8))),0))+(-MAX(0,((((Assumptions!$B$5*8760*$B$16*(1-Assumptions!$B$16)^(8-1)/1000)*$C$16/10)+(-Assumptions!$B$17*(1+Assumptions!$B$18)^(8-1)))+IF(8<=Assumptions!$B$20,-(Assumptions!$B$7*$D$16)/Assumptions!$B$20,0)+IF(8<=Assumptions!$B$12,IPMT(Assumptions!$B$11,8,Assumptions!$B$12,((Assumptions!$B$7*$D$16)*(1-Assumptions!$B$8))),0)))*Assumptions!$B$19))-(IF(8<=Assumptions!$B$20,-(Assumptions!$B$7*$D$16)/Assumptions!$B$20,0))+(IF(8<=Assumptions!$B$12,PPMT(Assumptions!$B$11,8,Assumptions!$B$12,((Assumptions!$B$7*$D$16)*(1-Assumptions!$B$8))),0)) -> 0.90391839 | K26: =(((((Assumptions!$B$5*8760*$B$16*(1-Assumptions!$B$16)^(9-1)/1000)*$C$16/10)+(-Assumptions!$B$17*(1+Assumptions!$B$18)^(9-1)))+IF(9<=Assumptions!$B$20,-(Assumptions!$B$7*$D$16)/Assumptions!$B$20,0)+IF(9<=Assumptions!$B$12,IPMT(Assumptions!$B$11,9,Assumptions!$B$12,((Assumptions!$B$7*$D$16)*(1-Assumptions!$B$8))),0))+(-MAX(0,((((Assumptions!$B$5*8760*$B$16*(1-Assumptions!$B$16)^(9-1)/1000)*$C$16/10)+(-Assumptions!$B$17*(1+Assumptions!$B$18)^(9-1)))+IF(9<=Assumptions!$B$20,-(Assumptions!$B$7*$D$16)/Assumptions!$B$20,0)+IF(9<=Assumptions!$B$12,IPMT(Assumptions!$B$11,9,Assumptions!$B$12,((Assumptions!$B$7*$D$16)*(1-Assumptions!$B$8))),0)))*Assumptions!$B$19))-(IF(9<=Assumptions!$B$20,-(Assumptions!$B$7*$D$16)/Assumptions!$B$20,0))+(IF(9<=Assumptions!$B$12,PPMT(Assumptions!$B$11,9,Assumptions!$B$12,((Assumptions!$B$7*$D$16)*(1-Assumptions!$B$8))),0)) -> 0.82122449 | L26: =(((((Assumptions!$B$5*8760*$B$16*(1-Assumptions!$B$16)^(10-1)/1000)*$C$16/10)+(-Assumptions!$B$17*(1+Assumptions!$B$18)^(10-1)))+IF(10<=Assumptions!$B$20,-(Assumptions!$B$7*$D$16)/Assumptions!$B$20,0)+IF(10<=Assumptions!$B$12,IPMT(Assumptions!$B$11,10,Assumptions!$B$12,((Assumptions!$B$7*$D$16)*(1-Assumptions!$B$8))),0))+(-MAX(0,((((Assumptions!$B$5*8760*$B$16*(1-Assumptions!$B$16)^(10-1)/1000)*$C$16/10)+(-Assumptions!$B$17*(1+Assumptions!$B$18)^(10-1)))+IF(10<=Assumptions!$B$20,-(Assumptions!$B$7*$D$16)/Assumptions!$B$20,0)+IF(10<=Assumptions!$B$12,IPMT(Assumptions!$B$11,10,Assumptions!$B$12,((Assumptions!$B$7*$D$16)*(1-Assumptions!$B$8))),0)))*Assumptions!$B$19))-(IF(10<=Assumptions!$B$20,-(Assumptions!$B$7*$D$16)/Assumptions!$B$20,0))+(IF(10<=Assumptions!$B$12,PPMT(Assumptions!$B$11,10,Assumptions!$B$12,((Assumptions!$B$7*$D$16)*(1-Assumptions!$B$8))),0)) -> 0.73399955 | M26: =(((((Assumptions!$B$5*8760*$B$16*(1-Assumptions!$B$16)^(11-1)/1000)*$C$16/10)+(-Assumptions!$B$17*(1+Assumptions!$B$18)^(11-1)))+IF(11<=Assumptions!$B$20,-(Assumptions!$B$7*$D$16)/Assumptions!$B$20,0)+IF(11<=Assumptions!$B$12,IPMT(Assumptions!$B$11,11,Assumptions!$B$12,((Assumptions!$B$7*$D$16)*(1-Assumptions!$B$8))),0))+(-MAX(0,((((Assumptions!$B$5*8760*$B$16*(1-Assumptions!$B$16)^(11-1)/1000)*$C$16/10)+(-Assumptions!$B$17*(1+Assumptions!$B$18)^(11-1)))+IF(11<=Assumptions!$B$20,-(Assumptions!$B$7*$D$16)/Assumptions!$B$20,0)+IF(11<=Assumptions!$B$12,IPMT(Assumptions!$B$11,11,Assumptions!$B$12,((Assumptions!$B$7*$D$16)*(1-Assumptions!$B$8))),0)))*Assumptions!$B$19))-(IF(11<=Assumptions!$B$20,-(Assumptions!$B$7*$D$16)/Assumptions!$B$20,0))+(IF(11<=Assumptions!$B$12,PPMT(Assumptions!$B$11,11,Assumptions!$B$12,((Assumptions!$B$7*$D$16)*(1-Assumptions!$B$8))),0)) -> 0.64187928 | N26: =(((((Assumptions!$B$5*8760*$B$16*(1-Assumptions!$B$16)^(12-1)/1000)*$C$16/10)+(-Assumptions!$B$17*(1+Assumptions!$B$18)^(12-1)))+IF(12<=Assumptions!$B$20,-(Assumptions!$B$7*$D$16)/Assumptions!$B$20,0)+IF(12<=Assumptions!$B$12,IPMT(Assumptions!$B$11,12,Assumptions!$B$12,((Assumptions!$B$7*$D$16)*(1-Assumptions!$B$8))),0))+(-MAX(0,((((Assumptions!$B$5*8760*$B$16*(1-Assumptions!$B$16)^(12-1)/1000)*$C$16/10)+(-Assumptions!$B$17*(1+Assumptions!$B$18)^(12-1)))+IF(12<=Assumptions!$B$20,-(Assumptions!$B$7*$D$16)/Assumptions!$B$20,0)+IF(12<=Assumptions!$B$12,IPMT(Assumptions!$B$11,12,Assumptions!$B$12,((Assumptions!$B$7*$D$16)*(1-Assumptions!$B$8))),0)))*Assumptions!$B$19))-(IF(12<=Assumptions!$B$20,-(Assumptions!$B$7*$D$16)/Assumptions!$B$20,0))+(IF(12<=Assumptions!$B$12,PPMT(Assumptions!$B$11,12,Assumptions!$B$12,((Assumptions!$B$7*$D$16)*(1-Assumptions!$B$8))),0)) -> 0.54446927 | O26: =(((((Assumptions!$B$5*8760*$B$16*(1-Assumptions!$B$16)^(13-1)/1000)*$C$16/10)+(-Assumptions!$B$17*(1+Assumptions!$B$18)^(13-1)))+IF(13<=Assumptions!$B$20,-(Assumptions!$B$7*$D$16)/Assumptions!$B$20,0)+IF(13<=Assumptions!$B$12,IPMT(Assumptions!$B$11,13,Assumptions!$B$12,((Assumptions!$B$7*$D$16)*(1-Assumptions!$B$8))),0))+(-MAX(0,((((Assumptions!$B$5*8760*$B$16*(1-Assumptions!$B$16)^(13-1)/1000)*$C$16/10)+(-Assumptions!$B$17*(1+Assumptions!$B$18)^(13-1)))+IF(13<=Assumptions!$B$20,-(Assumptions!$B$7*$D$16)/Assumptions!$B$20,0)+IF(13<=Assumptions!$B$12,IPMT(Assumptions!$B$11,13,Assumptions!$B$12,((Assumptions!$B$7*$D$16)*(1-Assumptions!$B$8))),0)))*Assumptions!$B$19))-(IF(13<=Assumptions!$B$20,-(Assumptions!$B$7*$D$16)/Assumptions!$B$20,0))+(IF(13<=Assumptions!$B$12,PPMT(Assumptions!$B$11,13,Assumptions!$B$12,((Assumptions!$B$7*$D$16)*(1-Assumptions!$B$8))),0)) -> 0.44134243 | P26: =(((((Assumptions!$B$5*8760*$B$16*(1-Assumptions!$B$16)^(14-1)/1000)*$C$16/10)+(-Assumptions!$B$17*(1+Assumptions!$B$18)^(14-1)))+IF(14<=Assumptions!$B$20,-(Assumptions!$B$7*$D$16)/Assumptions!$B$20,0)+IF(14<=Assumptions!$B$12,IPMT(Assumptions!$B$11,14,Assumptions!$B$12,((Assumptions!$B$7*$D$16)*(1-Assumptions!$B$8))),0))+(-MAX(0,((((Assumptions!$B$5*8760*$B$16*(1-Assumptions!$B$16)^(14-1)/1000)*$C$16/10)+(-Assumptions!$B$17*(1+Assumptions!$B$18)^(14-1)))+IF(14<=Assumptions!$B$20,-(Assumptions!$B$7*$D$16)/Assumptions!$B$20,0)+IF(14<=Assumptions!$B$12,IPMT(Assumptions!$B$11,14,Assumptions!$B$12,((Assumptions!$B$7*$D$16)*(1-Assumptions!$B$8))),0)))*Assumptions!$B$19))-(IF(14<=Assumptions!$B$20,-(Assumptions!$B$7*$D$16)/Assumptions!$B$20,0))+(IF(14<=Assumptions!$B$12,PPMT(Assumptions!$B$11,14,Assumptions!$B$12,((Assumptions!$B$7*$D$16)*(1-Assumptions!$B$8))),0)) -> 0.33203618 | Q26: =(((((Assumptions!$B$5*8760*$B$16*(1-Assumptions!$B$16)^(15-1)/1000)*$C$16/10)+(-Assumptions!$B$17*(1+Assumptions!$B$18)^(15-1)))+IF(15<=Assumptions!$B$20,-(Assumptions!$B$7*$D$16)/Assumptions!$B$20,0)+IF(15<=Assumptions!$B$12,IPMT(Assumptions!$B$11,15,Assumptions!$B$12,((Assumptions!$B$7*$D$16)*(1-Assumptions!$B$8))),0))+(-MAX(0,((((Assumptions!$B$5*8760*$B$16*(1-Assumptions!$B$16)^(15-1)/1000)*$C$16/10)+(-Assumptions!$B$17*(1+Assumptions!$B$18)^(15-1)))+IF(15<=Assumptions!$B$20,-(Assumptions!$B$7*$D$16)/Assumptions!$B$20,0)+IF(15<=Assumptions!$B$12,IPMT(Assumptions!$B$11,15,Assumptions!$B$12,((Assumptions!$B$7*$D$16)*(1-Assumptions!$B$8))),0)))*Assumptions!$B$19))-(IF(15<=Assumptions!$B$20,-(Assumptions!$B$7*$D$16)/Assumptions!$B$20,0))+(IF(15<=Assumptions!$B$12,PPMT(Assumptions!$B$11,15,Assumptions!$B$12,((Assumptions!$B$7*$D$16)*(1-Assumptions!$B$8))),0)) -> 0.21604941 | R26: =(((((Assumptions!$B$5*8760*$B$16*(1-Assumptions!$B$16)^(16-1)/1000)*$C$16/10)+(-Assumptions!$B$17*(1+Assumptions!$B$18)^(16-1)))+IF(16<=Assumptions!$B$20,-(Assumptions!$B$7*$D$16)/Assumptions!$B$20,0)+IF(16<=Assumptions!$B$12,IPMT(Assumptions!$B$11,16,Assumptions!$B$12,((Assumptions!$B$7*$D$16)*(1-Assumptions!$B$8))),0))+(-MAX(0,((((Assumptions!$B$5*8760*$B$16*(1-Assumptions!$B$16)^(16-1)/1000)*$C$16/10)+(-Assumptions!$B$17*(1+Assumptions!$B$18)^(16-1)))+IF(16<=Assumptions!$B$20,-(Assumptions!$B$7*$D$16)/Assumptions!$B$20,0)+IF(16<=Assumptions!$B$12,IPMT(Assumptions!$B$11,16,Assumptions!$B$12,((Assumptions!$B$7*$D$16)*(1-Assumptions!$B$8))),0)))*Assumptions!$B$19))-(IF(16<=Assumptions!$B$20,-(Assumptions!$B$7*$D$16)/Assumptions!$B$20,0))+(IF(16<=Assumptions!$B$12,PPMT(Assumptions!$B$11,16,Assumptions!$B$12,((Assumptions!$B$7*$D$16)*(1-Assumptions!$B$8))),0)) -> 3.3493849 | S26: =(((((Assumptions!$B$5*8760*$B$16*(1-Assumptions!$B$16)^(17-1)/1000)*$C$16/10)+(-Assumptions!$B$17*(1+Assumptions!$B$18)^(17-1)))+IF(17<=Assumptions!$B$20,-(Assumptions!$B$7*$D$16)/Assumptions!$B$20,0)+IF(17<=Assumptions!$B$12,IPMT(Assumptions!$B$11,17,Assumptions!$B$12,((Assumptions!$B$7*$D$16)*(1-Assumptions!$B$8))),0))+(-MAX(0,((((Assumptions!$B$5*8760*$B$16*(1-Assumptions!$B$16)^(17-1)/1000)*$C$16/10)+(-Assumptions!$B$17*(1+Assumptions!$B$18)^(17-1)))+IF(17<=Assumptions!$B$20,-(Assumptions!$B$7*$D$16)/Assumptions!$B$20,0)+IF(17<=Assumptions!$B$12,IPMT(Assumptions!$B$11,17,Assumptions!$B$12,((Assumptions!$B$7*$D$16)*(1-Assumptions!$B$8))),0)))*Assumptions!$B$19))-(IF(17<=Assumptions!$B$20,-(Assumptions!$B$7*$D$16)/Assumptions!$B$20,0))+(IF(17<=Assumptions!$B$12,PPMT(Assumptions!$B$11,17,Assumptions!$B$12,((Assumptions!$B$7*$D$16)*(1-Assumptions!$B$8))),0)) -> 3.291635 | T26: =(((((Assumptions!$B$5*8760*$B$16*(1-Assumptions!$B$16)^(18-1)/1000)*$C$16/10)+(-Assumptions!$B$17*(1+Assumptions!$B$18)^(18-1)))+IF(18<=Assumptions!$B$20,-(Assumptions!$B$7*$D$16)/Assumptions!$B$20,0)+IF(18<=Assumptions!$B$12,IPMT(Assumptions!$B$11,18,Assumptions!$B$12,((Assumptions!$B$7*$D$16)*(1-Assumptions!$B$8))),0))+(-MAX(0,((((Assumptions!$B$5*8760*$B$16*(1-Assumptions!$B$16)^(18-1)/1000)*$C$16/10)+(-Assumptions!$B$17*(1+Assumptions!$B$18)^(18-1)))+IF(18<=Assumptions!$B$20,-(Assumptions!$B$7*$D$16)/Assumptions!$B$20,0)+IF(18<=Assumptions!$B$12,IPMT(Assumptions!$B$11,18,Assumptions!$B$12,((Assumptions!$B$7*$D$16)*(1-Assumptions!$B$8))),0)))*Assumptions!$B$19))-(IF(18<=Assumptions!$B$20,-(Assumptions!$B$7*$D$16)/Assumptions!$B$20,0))+(IF(18<=Assumptions!$B$12,PPMT(Assumptions!$B$11,18,Assumptions!$B$12,((Assumptions!$B$7*$D$16)*(1-Assumptions!$B$8))),0)) -> 3.2320301 | U26: =(((((Assumptions!$B$5*8760*$B$16*(1-Assumptions!$B$16)^(19-1)/1000)*$C$16/10)+(-Assumptions!$B$17*(1+Assumptions!$B$18)^(19-1)))+IF(19<=Assumptions!$B$20,-(Assumptions!$B$7*$D$16)/Assumptions!$B$20,0)+IF(19<=Assumptions!$B$12,IPMT(Assumptions!$B$11,19,Assumptions!$B$12,((Assumptions!$B$7*$D$16)*(1-Assumptions!$B$8))),0))+(-MAX(0,((((Assumptions!$B$5*8760*$B$16*(1-Assumptions!$B$16)^(19-1)/1000)*$C$16/10)+(-Assumptions!$B$17*(1+Assumptions!$B$18)^(19-1)))+IF(19<=Assumptions!$B$20,-(Assumptions!$B$7*$D$16)/Assumptions!$B$20,0)+IF(19<=Assumptions!$B$12,IPMT(Assumptions!$B$11,19,Assumptions!$B$12,((Assumptions!$B$7*$D$16)*(1-Assumptions!$B$8))),0)))*Assumptions!$B$19))-(IF(19<=Assumptions!$B$20,-(Assumptions!$B$7*$D$16)/Assumptions!$B$20,0))+(IF(19<=Assumptions!$B$12,PPMT(Assumptions!$B$11,19,Assumptions!$B$12,((Assumptions!$B$7*$D$16)*(1-Assumptions!$B$8))),0)) -> 3.170472 | V26: =(((((Assumptions!$B$5*8760*$B$16*(1-Assumptions!$B$16)^(20-1)/1000)*$C$16/10)+(-Assumptions!$B$17*(1+Assumptions!$B$18)^(20-1)))+IF(20<=Assumptions!$B$20,-(Assumptions!$B$7*$D$16)/Assumptions!$B$20,0)+IF(20<=Assumptions!$B$12,IPMT(Assumptions!$B$11,20,Assumptions!$B$12,((Assumptions!$B$7*$D$16)*(1-Assumptions!$B$8))),0))+(-MAX(0,((((Assumptions!$B$5*8760*$B$16*(1-Assumptions!$B$16)^(20-1)/1000)*$C$16/10)+(-Assumptions!$B$17*(1+Assumptions!$B$18)^(20-1)))+IF(20<=Assumptions!$B$20,-(Assumptions!$B$7*$D$16)/Assumptions!$B$20,0)+IF(20<=Assumptions!$B$12,IPMT(Assumptions!$B$11,20,Assumptions!$B$12,((Assumptions!$B$7*$D$16)*(1-Assumptions!$B$8))),0)))*Assumptions!$B$19))-(IF(20<=Assumptions!$B$20,-(Assumptions!$B$7*$D$16)/Assumptions!$B$20,0))+(IF(20<=Assumptions!$B$12,PPMT(Assumptions!$B$11,20,Assumptions!$B$12,((Assumptions!$B$7*$D$16)*(1-Assumptions!$B$8))),0)) -> 3.1068582 | W26: =(((((Assumptions!$B$5*8760*$B$16*(1-Assumptions!$B$16)^(21-1)/1000)*$C$16/10)+(-Assumptions!$B$17*(1+Assumptions!$B$18)^(21-1)))+IF(21<=Assumptions!$B$20,-(Assumptions!$B$7*$D$16)/Assumptions!$B$20,0)+IF(21<=Assumptions!$B$12,IPMT(Assumptions!$B$11,21,Assumptions!$B$12,((Assumptions!$B$7*$D$16)*(1-Assumptions!$B$8))),0))+(-MAX(0,((((Assumptions!$B$5*8760*$B$16*(1-Assumptions!$B$16)^(21-1)/1000)*$C$16/10)+(-Assumptions!$B$17*(1+Assumptions!$B$18)^(21-1)))+IF(21<=Assumptions!$B$20,-(Assumptions!$B$7*$D$16)/Assumptions!$B$20,0)+IF(21<=Assumptions!$B$12,IPMT(Assumptions!$B$11,21,Assumptions!$B$12,((Assumptions!$B$7*$D$16)*(1-Assumptions!$B$8))),0)))*Assumptions!$B$19))-(IF(21<=Assumptions!$B$20,-(Assumptions!$B$7*$D$16)/Assumptions!$B$20,0))+(IF(21<=Assumptions!$B$12,PPMT(Assumptions!$B$11,21,Assumptions!$B$12,((Assumptions!$B$7*$D$16)*(1-Assumptions!$B$8))),0)) -> 3.0410805 | X26: =(((((Assumptions!$B$5*8760*$B$16*(1-Assumptions!$B$16)^(22-1)/1000)*$C$16/10)+(-Assumptions!$B$17*(1+Assumptions!$B$18)^(22-1)))+IF(22<=Assumptions!$B$20,-(Assumptions!$B$7*$D$16)/Assumptions!$B$20,0)+IF(22<=Assumptions!$B$12,IPMT(Assumptions!$B$11,22,Assumptions!$B$12,((Assumptions!$B$7*$D$16)*(1-Assumptions!$B$8))),0))+(-MAX(0,((((Assumptions!$B$5*8760*$B$16*(1-Assumptions!$B$16)^(22-1)/1000)*$C$16/10)+(-Assumptions!$B$17*(1+Assumptions!$B$18)^(22-1)))+IF(22<=Assumptions!$B$20,-(Assumptions!$B$7*$D$16)/Assumptions!$B$20,0)+IF(22<=Assumptions!$B$12,IPMT(Assumptions!$B$11,22,Assumptions!$B$12,((Assumptions!$B$7*$D$16)*(1-Assumptions!$B$8))),0)))*Assumptions!$B$19))-(IF(22<=Assumptions!$B$20,-(Assumptions!$B$7*$D$16)/Assumptions!$B$20,0))+(IF(22<=Assumptions!$B$12,PPMT(Assumptions!$B$11,22,Assumptions!$B$12,((Assumptions!$B$7*$D$16)*(1-Assumptions!$B$8))),0)) -> 2.9730259 | Y26: =(((((Assumptions!$B$5*8760*$B$16*(1-Assumptions!$B$16)^(23-1)/1000)*$C$16/10)+(-Assumptions!$B$17*(1+Assumptions!$B$18)^(23-1)))+IF(23<=Assumptions!$B$20,-(Assumptions!$B$7*$D$16)/Assumptions!$B$20,0)+IF(23<=Assumptions!$B$12,IPMT(Assumptions!$B$11,23,Assumptions!$B$12,((Assumptions!$B$7*$D$16)*(1-Assumptions!$B$8))),0))+(-MAX(0,((((Assumptions!$B$5*8760*$B$16*(1-Assumptions!$B$16)^(23-1)/1000)*$C$16/10)+(-Assumptions!$B$17*(1+Assumptions!$B$18)^(23-1)))+IF(23<=Assumptions!$B$20,-(Assumptions!$B$7*$D$16)/Assumptions!$B$20,0)+IF(23<=Assumptions!$B$12,IPMT(Assumptions!$B$11,23,Assumptions!$B$12,((Assumptions!$B$7*$D$16)*(1-Assumptions!$B$8))),0)))*Assumptions!$B$19))-(IF(23<=Assumptions!$B$20,-(Assumptions!$B$7*$D$16)/Assumptions!$B$20,0))+(IF(23<=Assumptions!$B$12,PPMT(Assumptions!$B$11,23,Assumptions!$B$12,((Assumptions!$B$7*$D$16)*(1-Assumptions!$B$8))),0)) -> 2.9025753 | Z26: =(((((Assumptions!$B$5*8760*$B$16*(1-Assumptions!$B$16)^(24-1)/1000)*$C$16/10)+(-Assumptions!$B$17*(1+Assumptions!$B$18)^(24-1)))+IF(24<=Assumptions!$B$20,-(Assumptions!$B$7*$D$16)/Assumptions!$B$20,0)+IF(24<=Assumptions!$B$12,IPMT(Assumptions!$B$11,24,Assumptions!$B$12,((Assumptions!$B$7*$D$16)*(1-Assumptions!$B$8))),0))+(-MAX(0,((((Assumptions!$B$5*8760*$B$16*(1-Assumptions!$B$16)^(24-1)/1000)*$C$16/10)+(-Assumptions!$B$17*(1+Assumptions!$B$18)^(24-1)))+IF(24<=Assumptions!$B$20,-(Assumptions!$B$7*$D$16)/Assumptions!$B$20,0)+IF(24<=Assumptions!$B$12,IPMT(Assumptions!$B$11,24,Assumptions!$B$12,((Assumptions!$B$7*$D$16)*(1-Assumptions!$B$8))),0)))*Assumptions!$B$19))-(IF(24<=Assumptions!$B$20,-(Assumptions!$B$7*$D$16)/Assumptions!$B$20,0))+(IF(24<=Assumptions!$B$12,PPMT(Assumptions!$B$11,24,Assumptions!$B$12,((Assumptions!$B$7*$D$16)*(1-Assumptions!$B$8))),0)) -> 2.8296039 | AA26: =(((((Assumptions!$B$5*8760*$B$16*(1-Assumptions!$B$16)^(25-1)/1000)*$C$16/10)+(-Assumptions!$B$17*(1+Assumptions!$B$18)^(25-1)))+IF(25<=Assumptions!$B$20,-(Assumptions!$B$7*$D$16)/Assumptions!$B$20,0)+IF(25<=Assumptions!$B$12,IPMT(Assumptions!$B$11,25,Assumptions!$B$12,((Assumptions!$B$7*$D$16)*(1-Assumptions!$B$8))),0))+(-MAX(0,((((Assumptions!$B$5*8760*$B$16*(1-Assumptions!$B$16)^(25-1)/1000)*$C$16/10)+(-Assumptions!$B$17*(1+Assumptions!$B$18)^(25-1)))+IF(25<=Assumptions!$B$20,-(Assumptions!$B$7*$D$16)/Assumptions!$B$20,0)+IF(25<=Assumptions!$B$12,IPMT(Assumptions!$B$11,25,Assumptions!$B$12,((Assumptions!$B$7*$D$16)*(1-Assumptions!$B$8))),0)))*Assumptions!$B$19))-(IF(25<=Assumptions!$B$20,-(Assumptions!$B$7*$D$16)/Assumptions!$B$20,0))+(IF(25<=Assumptions!$B$12,PPMT(Assumptions!$B$11,25,Assumptions!$B$12,((Assumptions!$B$7*$D$16)*(1-Assumptions!$B$8))),0)) -> 2.7539807
A27: Tariff haircut 10% | B27: =-((Assumptions!$B$7*$D$17)*Assumptions!$B$8) -> -11.25 | C27: =(((((Assumptions!$B$5*8760*$B$17*(1-Assumptions!$B$16)^(1-1)/1000)*$C$17/10)+(-Assumptions!$B$17*(1+Assumptions!$B$18)^(1-1)))+IF(1<=Assumptions!$B$20,-(Assumptions!$B$7*$D$17)/Assumptions!$B$20,0)+IF(1<=Assumptions!$B$12,IPMT(Assumptions!$B$11,1,Assumptions!$B$12,((Assumptions!$B$7*$D$17)*(1-Assumptions!$B$8))),0))+(-MAX(0,((((Assumptions!$B$5*8760*$B$17*(1-Assumptions!$B$16)^(1-1)/1000)*$C$17/10)+(-Assumptions!$B$17*(1+Assumptions!$B$18)^(1-1)))+IF(1<=Assumptions!$B$20,-(Assumptions!$B$7*$D$17)/Assumptions!$B$20,0)+IF(1<=Assumptions!$B$12,IPMT(Assumptions!$B$11,1,Assumptions!$B$12,((Assumptions!$B$7*$D$17)*(1-Assumptions!$B$8))),0)))*Assumptions!$B$19))-(IF(1<=Assumptions!$B$20,-(Assumptions!$B$7*$D$17)/Assumptions!$B$20,0))+(IF(1<=Assumptions!$B$12,PPMT(Assumptions!$B$11,1,Assumptions!$B$12,((Assumptions!$B$7*$D$17)*(1-Assumptions!$B$8))),0)) -> 0.97648733 | D27: =(((((Assumptions!$B$5*8760*$B$17*(1-Assumptions!$B$16)^(2-1)/1000)*$C$17/10)+(-Assumptions!$B$17*(1+Assumptions!$B$18)^(2-1)))+IF(2<=Assumptions!$B$20,-(Assumptions!$B$7*$D$17)/Assumptions!$B$20,0)+IF(2<=Assumptions!$B$12,IPMT(Assumptions!$B$11,2,Assumptions!$B$12,((Assumptions!$B$7*$D$17)*(1-Assumptions!$B$8))),0))+(-MAX(0,((((Assumptions!$B$5*8760*$B$17*(1-Assumptions!$B$16)^(2-1)/1000)*$C$17/10)+(-Assumptions!$B$17*(1+Assumptions!$B$18)^(2-1)))+IF(2<=Assumptions!$B$20,-(Assumptions!$B$7*$D$17)/Assumptions!$B$20,0)+IF(2<=Assumptions!$B$12,IPMT(Assumptions!$B$11,2,Assumptions!$B$12,((Assumptions!$B$7*$D$17)*(1-Assumptions!$B$8))),0)))*Assumptions!$B$19))-(IF(2<=Assumptions!$B$20,-(Assumptions!$B$7*$D$17)/Assumptions!$B$20,0))+(IF(2<=Assumptions!$B$12,PPMT(Assumptions!$B$11,2,Assumptions!$B$12,((Assumptions!$B$7*$D$17)*(1-Assumptions!$B$8))),0)) -> 0.91940926 | E27: =(((((Assumptions!$B$5*8760*$B$17*(1-Assumptions!$B$16)^(3-1)/1000)*$C$17/10)+(-Assumptions!$B$17*(1+Assumptions!$B$18)^(3-1)))+IF(3<=Assumptions!$B$20,-(Assumptions!$B$7*$D$17)/Assumptions!$B$20,0)+IF(3<=Assumptions!$B$12,IPMT(Assumptions!$B$11,3,Assumptions!$B$12,((Assumptions!$B$7*$D$17)*(1-Assumptions!$B$8))),0))+(-MAX(0,((((Assumptions!$B$5*8760*$B$17*(1-Assumptions!$B$16)^(3-1)/1000)*$C$17/10)+(-Assumptions!$B$17*(1+Assumptions!$B$18)^(3-1)))+IF(3<=Assumptions!$B$20,-(Assumptions!$B$7*$D$17)/Assumptions!$B$20,0)+IF(3<=Assumptions!$B$12,IPMT(Assumptions!$B$11,3,Assumptions!$B$12,((Assumptions!$B$7*$D$17)*(1-Assumptions!$B$8))),0)))*Assumptions!$B$19))-(IF(3<=Assumptions!$B$20,-(Assumptions!$B$7*$D$17)/Assumptions!$B$20,0))+(IF(3<=Assumptions!$B$12,PPMT(Assumptions!$B$11,3,Assumptions!$B$12,((Assumptions!$B$7*$D$17)*(1-Assumptions!$B$8))),0)) -> 0.85967431 | F27: =(((((Assumptions!$B$5*8760*$B$17*(1-Assumptions!$B$16)^(4-1)/1000)*$C$17/10)+(-Assumptions!$B$17*(1+Assumptions!$B$18)^(4-1)))+IF(4<=Assumptions!$B$20,-(Assumptions!$B$7*$D$17)/Assumptions!$B$20,0)+IF(4<=Assumptions!$B$12,IPMT(Assumptions!$B$11,4,Assumptions!$B$12,((Assumptions!$B$7*$D$17)*(1-Assumptions!$B$8))),0))+(-MAX(0,((((Assumptions!$B$5*8760*$B$17*(1-Assumptions!$B$16)^(4-1)/1000)*$C$17/10)+(-Assumptions!$B$17*(1+Assumptions!$B$18)^(4-1)))+IF(4<=Assumptions!$B$20,-(Assumptions!$B$7*$D$17)/Assumptions!$B$20,0)+IF(4<=Assumptions!$B$12,IPMT(Assumptions!$B$11,4,Assumptions!$B$12,((Assumptions!$B$7*$D$17)*(1-Assumptions!$B$8))),0)))*Assumptions!$B$19))-(IF(4<=Assumptions!$B$20,-(Assumptions!$B$7*$D$17)/Assumptions!$B$20,0))+(IF(4<=Assumptions!$B$12,PPMT(Assumptions!$B$11,4,Assumptions!$B$12,((Assumptions!$B$7*$D$17)*(1-Assumptions!$B$8))),0)) -> 0.79707221 | G27: =(((((Assumptions!$B$5*8760*$B$17*(1-Assumptions!$B$16)^(5-1)/1000)*$C$17/10)+(-Assumptions!$B$17*(1+Assumptions!$B$18)^(5-1)))+IF(5<=Assumptions!$B$20,-(Assumptions!$B$7*$D$17)/Assumptions!$B$20,0)+IF(5<=Assumptions!$B$12,IPMT(Assumptions!$B$11,5,Assumptions!$B$12,((Assumptions!$B$7*$D$17)*(1-Assumptions!$B$8))),0))+(-MAX(0,((((Assumptions!$B$5*8760*$B$17*(1-Assumptions!$B$16)^(5-1)/1000)*$C$17/10)+(-Assumptions!$B$17*(1+Assumptions!$B$18)^(5-1)))+IF(5<=Assumptions!$B$20,-(Assumptions!$B$7*$D$17)/Assumptions!$B$20,0)+IF(5<=Assumptions!$B$12,IPMT(Assumptions!$B$11,5,Assumptions!$B$12,((Assumptions!$B$7*$D$17)*(1-Assumptions!$B$8))),0)))*Assumptions!$B$19))-(IF(5<=Assumptions!$B$20,-(Assumptions!$B$7*$D$17)/Assumptions!$B$20,0))+(IF(5<=Assumptions!$B$12,PPMT(Assumptions!$B$11,5,Assumptions!$B$12,((Assumptions!$B$7*$D$17)*(1-Assumptions!$B$8))),0)) -> 0.73137568 | H27: =(((((Assumptions!$B$5*8760*$B$17*(1-Assumptions!$B$16)^(6-1)/1000)*$C$17/10)+(-Assumptions!$B$17*(1+Assumptions!$B$18)^(6-1)))+IF(6<=Assumptions!$B$20,-(Assumptions!$B$7*$D$17)/Assumptions!$B$20,0)+IF(6<=Assumptions!$B$12,IPMT(Assumptions!$B$11,6,Assumptions!$B$12,((Assumptions!$B$7*$D$17)*(1-Assumptions!$B$8))),0))+(-MAX(0,((((Assumptions!$B$5*8760*$B$17*(1-Assumptions!$B$16)^(6-1)/1000)*$C$17/10)+(-Assumptions!$B$17*(1+Assumptions!$B$18)^(6-1)))+IF(6<=Assumptions!$B$20,-(Assumptions!$B$7*$D$17)/Assumptions!$B$20,0)+IF(6<=Assumptions!$B$12,IPMT(Assumptions!$B$11,6,Assumptions!$B$12,((Assumptions!$B$7*$D$17)*(1-Assumptions!$B$8))),0)))*Assumptions!$B$19))-(IF(6<=Assumptions!$B$20,-(Assumptions!$B$7*$D$17)/Assumptions!$B$20,0))+(IF(6<=Assumptions!$B$12,PPMT(Assumptions!$B$11,6,Assumptions!$B$12,((Assumptions!$B$7*$D$17)*(1-Assumptions!$B$8))),0)) -> 0.662339 | I27: =(((((Assumptions!$B$5*8760*$B$17*(1-Assumptions!$B$16)^(7-1)/1000)*$C$17/10)+(-Assumptions!$B$17*(1+Assumptions!$B$18)^(7-1)))+IF(7<=Assumptions!$B$20,-(Assumptions!$B$7*$D$17)/Assumptions!$B$20,0)+IF(7<=Assumptions!$B$12,IPMT(Assumptions!$B$11,7,Assumptions!$B$12,((Assumptions!$B$7*$D$17)*(1-Assumptions!$B$8))),0))+(-MAX(0,((((Assumptions!$B$5*8760*$B$17*(1-Assumptions!$B$16)^(7-1)/1000)*$C$17/10)+(-Assumptions!$B$17*(1+Assumptions!$B$18)^(7-1)))+IF(7<=Assumptions!$B$20,-(Assumptions!$B$7*$D$17)/Assumptions!$B$20,0)+IF(7<=Assumptions!$B$12,IPMT(Assumptions!$B$11,7,Assumptions!$B$12,((Assumptions!$B$7*$D$17)*(1-Assumptions!$B$8))),0)))*Assumptions!$B$19))-(IF(7<=Assumptions!$B$20,-(Assumptions!$B$7*$D$17)/Assumptions!$B$20,0))+(IF(7<=Assumptions!$B$12,PPMT(Assumptions!$B$11,7,Assumptions!$B$12,((Assumptions!$B$7*$D$17)*(1-Assumptions!$B$8))),0)) -> 0.58969645 | J27: =(((((Assumptions!$B$5*8760*$B$17*(1-Assumptions!$B$16)^(8-1)/1000)*$C$17/10)+(-Assumptions!$B$17*(1+Assumptions!$B$18)^(8-1)))+IF(8<=Assumptions!$B$20,-(Assumptions!$B$7*$D$17)/Assumptions!$B$20,0)+IF(8<=Assumptions!$B$12,IPMT(Assumptions!$B$11,8,Assumptions!$B$12,((Assumptions!$B$7*$D$17)*(1-Assumptions!$B$8))),0))+(-MAX(0,((((Assumptions!$B$5*8760*$B$17*(1-Assumptions!$B$16)^(8-1)/1000)*$C$17/10)+(-Assumptions!$B$17*(1+Assumptions!$B$18)^(8-1)))+IF(8<=Assumptions!$B$20,-(Assumptions!$B$7*$D$17)/Assumptions!$B$20,0)+IF(8<=Assumptions!$B$12,IPMT(Assumptions!$B$11,8,Assumptions!$B$12,((Assumptions!$B$7*$D$17)*(1-Assumptions!$B$8))),0)))*Assumptions!$B$19))-(IF(8<=Assumptions!$B$20,-(Assumptions!$B$7*$D$17)/Assumptions!$B$20,0))+(IF(8<=Assumptions!$B$12,PPMT(Assumptions!$B$11,8,Assumptions!$B$12,((Assumptions!$B$7*$D$17)*(1-Assumptions!$B$8))),0)) -> 0.5131606 | K27: =(((((Assumptions!$B$5*8760*$B$17*(1-Assumptions!$B$16)^(9-1)/1000)*$C$17/10)+(-Assumptions!$B$17*(1+Assumptions!$B$18)^(9-1)))+IF(9<=Assumptions!$B$20,-(Assumptions!$B$7*$D$17)/Assumptions!$B$20,0)+IF(9<=Assumptions!$B$12,IPMT(Assumptions!$B$11,9,Assumptions!$B$12,((Assumptions!$B$7*$D$17)*(1-Assumptions!$B$8))),0))+(-MAX(0,((((Assumptions!$B$5*8760*$B$17*(1-Assumptions!$B$16)^(9-1)/1000)*$C$17/10)+(-Assumptions!$B$17*(1+Assumptions!$B$18)^(9-1)))+IF(9<=Assumptions!$B$20,-(Assumptions!$B$7*$D$17)/Assumptions!$B$20,0)+IF(9<=Assumptions!$B$12,IPMT(Assumptions!$B$11,9,Assumptions!$B$12,((Assumptions!$B$7*$D$17)*(1-Assumptions!$B$8))),0)))*Assumptions!$B$19))-(IF(9<=Assumptions!$B$20,-(Assumptions!$B$7*$D$17)/Assumptions!$B$20,0))+(IF(9<=Assumptions!$B$12,PPMT(Assumptions!$B$11,9,Assumptions!$B$12,((Assumptions!$B$7*$D$17)*(1-Assumptions!$B$8))),0)) -> 0.43242048 | L27: =(((((Assumptions!$B$5*8760*$B$17*(1-Assumptions!$B$16)^(10-1)/1000)*$C$17/10)+(-Assumptions!$B$17*(1+Assumptions!$B$18)^(10-1)))+IF(10<=Assumptions!$B$20,-(Assumptions!$B$7*$D$17)/Assumptions!$B$20,0)+IF(10<=Assumptions!$B$12,IPMT(Assumptions!$B$11,10,Assumptions!$B$12,((Assumptions!$B$7*$D$17)*(1-Assumptions!$B$8))),0))+(-MAX(0,((((Assumptions!$B$5*8760*$B$17*(1-Assumptions!$B$16)^(10-1)/1000)*$C$17/10)+(-Assumptions!$B$17*(1+Assumptions!$B$18)^(10-1)))+IF(10<=Assumptions!$B$20,-(Assumptions!$B$7*$D$17)/Assumptions!$B$20,0)+IF(10<=Assumptions!$B$12,IPMT(Assumptions!$B$11,10,Assumptions!$B$12,((Assumptions!$B$7*$D$17)*(1-Assumptions!$B$8))),0)))*Assumptions!$B$19))-(IF(10<=Assumptions!$B$20,-(Assumptions!$B$7*$D$17)/Assumptions!$B$20,0))+(IF(10<=Assumptions!$B$12,PPMT(Assumptions!$B$11,10,Assumptions!$B$12,((Assumptions!$B$7*$D$17)*(1-Assumptions!$B$8))),0)) -> 0.34713957 | M27: =(((((Assumptions!$B$5*8760*$B$17*(1-Assumptions!$B$16)^(11-1)/1000)*$C$17/10)+(-Assumptions!$B$17*(1+Assumptions!$B$18)^(11-1)))+IF(11<=Assumptions!$B$20,-(Assumptions!$B$7*$D$17)/Assumptions!$B$20,0)+IF(11<=Assumptions!$B$12,IPMT(Assumptions!$B$11,11,Assumptions!$B$12,((Assumptions!$B$7*$D$17)*(1-Assumptions!$B$8))),0))+(-MAX(0,((((Assumptions!$B$5*8760*$B$17*(1-Assumptions!$B$16)^(11-1)/1000)*$C$17/10)+(-Assumptions!$B$17*(1+Assumptions!$B$18)^(11-1)))+IF(11<=Assumptions!$B$20,-(Assumptions!$B$7*$D$17)/Assumptions!$B$20,0)+IF(11<=Assumptions!$B$12,IPMT(Assumptions!$B$11,11,Assumptions!$B$12,((Assumptions!$B$7*$D$17)*(1-Assumptions!$B$8))),0)))*Assumptions!$B$19))-(IF(11<=Assumptions!$B$20,-(Assumptions!$B$7*$D$17)/Assumptions!$B$20,0))+(IF(11<=Assumptions!$B$12,PPMT(Assumptions!$B$11,11,Assumptions!$B$12,((Assumptions!$B$7*$D$17)*(1-Assumptions!$B$8))),0)) -> 0.2569536 | N27: =(((((Assumptions!$B$5*8760*$B$17*(1-Assumptions!$B$16)^(12-1)/1000)*$C$17/10)+(-Assumptions!$B$17*(1+Assumptions!$B$18)^(12-1)))+IF(12<=Assumptions!$B$20,-(Assumptions!$B$7*$D$17)/Assumptions!$B$20,0)+IF(12<=Assumptions!$B$12,IPMT(Assumptions!$B$11,12,Assumptions!$B$12,((Assumptions!$B$7*$D$17)*(1-Assumptions!$B$8))),0))+(-MAX(0,((((Assumptions!$B$5*8760*$B$17*(1-Assumptions!$B$16)^(12-1)/1000)*$C$17/10)+(-Assumptions!$B$17*(1+Assumptions!$B$18)^(12-1)))+IF(12<=Assumptions!$B$20,-(Assumptions!$B$7*$D$17)/Assumptions!$B$20,0)+IF(12<=Assumptions!$B$12,IPMT(Assumptions!$B$11,12,Assumptions!$B$12,((Assumptions!$B$7*$D$17)*(1-Assumptions!$B$8))),0)))*Assumptions!$B$19))-(IF(12<=Assumptions!$B$20,-(Assumptions!$B$7*$D$17)/Assumptions!$B$20,0))+(IF(12<=Assumptions!$B$12,PPMT(Assumptions!$B$11,12,Assumptions!$B$12,((Assumptions!$B$7*$D$17)*(1-Assumptions!$B$8))),0)) -> 0.16146822 | O27: =(((((Assumptions!$B$5*8760*$B$17*(1-Assumptions!$B$16)^(13-1)/1000)*$C$17/10)+(-Assumptions!$B$17*(1+Assumptions!$B$18)^(13-1)))+IF(13<=Assumptions!$B$20,-(Assumptions!$B$7*$D$17)/Assumptions!$B$20,0)+IF(13<=Assumptions!$B$12,IPMT(Assumptions!$B$11,13,Assumptions!$B$12,((Assumptions!$B$7*$D$17)*(1-Assumptions!$B$8))),0))+(-MAX(0,((((Assumptions!$B$5*8760*$B$17*(1-Assumptions!$B$16)^(13-1)/1000)*$C$17/10)+(-Assumptions!$B$17*(1+Assumptions!$B$18)^(13-1)))+IF(13<=Assumptions!$B$20,-(Assumptions!$B$7*$D$17)/Assumptions!$B$20,0)+IF(13<=Assumptions!$B$12,IPMT(Assumptions!$B$11,13,Assumptions!$B$12,((Assumptions!$B$7*$D$17)*(1-Assumptions!$B$8))),0)))*Assumptions!$B$19))-(IF(13<=Assumptions!$B$20,-(Assumptions!$B$7*$D$17)/Assumptions!$B$20,0))+(IF(13<=Assumptions!$B$12,PPMT(Assumptions!$B$11,13,Assumptions!$B$12,((Assumptions!$B$7*$D$17)*(1-Assumptions!$B$8))),0)) -> 0.060256378 | P27: =(((((Assumptions!$B$5*8760*$B$17*(1-Assumptions!$B$16)^(14-1)/1000)*$C$17/10)+(-Assumptions!$B$17*(1+Assumptions!$B$18)^(14-1)))+IF(14<=Assumptions!$B$20,-(Assumptions!$B$7*$D$17)/Assumptions!$B$20,0)+IF(14<=Assumptions!$B$12,IPMT(Assumptions!$B$11,14,Assumptions!$B$12,((Assumptions!$B$7*$D$17)*(1-Assumptions!$B$8))),0))+(-MAX(0,((((Assumptions!$B$5*8760*$B$17*(1-Assumptions!$B$16)^(14-1)/1000)*$C$17/10)+(-Assumptions!$B$17*(1+Assumptions!$B$18)^(14-1)))+IF(14<=Assumptions!$B$20,-(Assumptions!$B$7*$D$17)/Assumptions!$B$20,0)+IF(14<=Assumptions!$B$12,IPMT(Assumptions!$B$11,14,Assumptions!$B$12,((Assumptions!$B$7*$D$17)*(1-Assumptions!$B$8))),0)))*Assumptions!$B$19))-(IF(14<=Assumptions!$B$20,-(Assumptions!$B$7*$D$17)/Assumptions!$B$20,0))+(IF(14<=Assumptions!$B$12,PPMT(Assumptions!$B$11,14,Assumptions!$B$12,((Assumptions!$B$7*$D$17)*(1-Assumptions!$B$8))),0)) -> -0.047144442 | Q27: =(((((Assumptions!$B$5*8760*$B$17*(1-Assumptions!$B$16)^(15-1)/1000)*$C$17/10)+(-Assumptions!$B$17*(1+Assumptions!$B$18)^(15-1)))+IF(15<=Assumptions!$B$20,-(Assumptions!$B$7*$D$17)/Assumptions!$B$20,0)+IF(15<=Assumptions!$B$12,IPMT(Assumptions!$B$11,15,Assumptions!$B$12,((Assumptions!$B$7*$D$17)*(1-Assumptions!$B$8))),0))+(-MAX(0,((((Assumptions!$B$5*8760*$B$17*(1-Assumptions!$B$16)^(15-1)/1000)*$C$17/10)+(-Assumptions!$B$17*(1+Assumptions!$B$18)^(15-1)))+IF(15<=Assumptions!$B$20,-(Assumptions!$B$7*$D$17)/Assumptions!$B$20,0)+IF(15<=Assumptions!$B$12,IPMT(Assumptions!$B$11,15,Assumptions!$B$12,((Assumptions!$B$7*$D$17)*(1-Assumptions!$B$8))),0)))*Assumptions!$B$19))-(IF(15<=Assumptions!$B$20,-(Assumptions!$B$7*$D$17)/Assumptions!$B$20,0))+(IF(15<=Assumptions!$B$12,PPMT(Assumptions!$B$11,15,Assumptions!$B$12,((Assumptions!$B$7*$D$17)*(1-Assumptions!$B$8))),0)) -> -0.1612353 | R27: =(((((Assumptions!$B$5*8760*$B$17*(1-Assumptions!$B$16)^(16-1)/1000)*$C$17/10)+(-Assumptions!$B$17*(1+Assumptions!$B$18)^(16-1)))+IF(16<=Assumptions!$B$20,-(Assumptions!$B$7*$D$17)/Assumptions!$B$20,0)+IF(16<=Assumptions!$B$12,IPMT(Assumptions!$B$11,16,Assumptions!$B$12,((Assumptions!$B$7*$D$17)*(1-Assumptions!$B$8))),0))+(-MAX(0,((((Assumptions!$B$5*8760*$B$17*(1-Assumptions!$B$16)^(16-1)/1000)*$C$17/10)+(-Assumptions!$B$17*(1+Assumptions!$B$18)^(16-1)))+IF(16<=Assumptions!$B$20,-(Assumptions!$B$7*$D$17)/Assumptions!$B$20,0)+IF(16<=Assumptions!$B$12,IPMT(Assumptions!$B$11,16,Assumptions!$B$12,((Assumptions!$B$7*$D$17)*(1-Assumptions!$B$8))),0)))*Assumptions!$B$19))-(IF(16<=Assumptions!$B$20,-(Assumptions!$B$7*$D$17)/Assumptions!$B$20,0))+(IF(16<=Assumptions!$B$12,PPMT(Assumptions!$B$11,16,Assumptions!$B$12,((Assumptions!$B$7*$D$17)*(1-Assumptions!$B$8))),0)) -> 2.9739866 | S27: =(((((Assumptions!$B$5*8760*$B$17*(1-Assumptions!$B$16)^(17-1)/1000)*$C$17/10)+(-Assumptions!$B$17*(1+Assumptions!$B$18)^(17-1)))+IF(17<=Assumptions!$B$20,-(Assumptions!$B$7*$D$17)/Assumptions!$B$20,0)+IF(17<=Assumptions!$B$12,IPMT(Assumptions!$B$11,17,Assumptions!$B$12,((Assumptions!$B$7*$D$17)*(1-Assumptions!$B$8))),0))+(-MAX(0,((((Assumptions!$B$5*8760*$B$17*(1-Assumptions!$B$16)^(17-1)/1000)*$C$17/10)+(-Assumptions!$B$17*(1+Assumptions!$B$18)^(17-1)))+IF(17<=Assumptions!$B$20,-(Assumptions!$B$7*$D$17)/Assumptions!$B$20,0)+IF(17<=Assumptions!$B$12,IPMT(Assumptions!$B$11,17,Assumptions!$B$12,((Assumptions!$B$7*$D$17)*(1-Assumptions!$B$8))),0)))*Assumptions!$B$19))-(IF(17<=Assumptions!$B$20,-(Assumptions!$B$7*$D$17)/Assumptions!$B$20,0))+(IF(17<=Assumptions!$B$12,PPMT(Assumptions!$B$11,17,Assumptions!$B$12,((Assumptions!$B$7*$D$17)*(1-Assumptions!$B$8))),0)) -> 2.9181137 | T27: =(((((Assumptions!$B$5*8760*$B$17*(1-Assumptions!$B$16)^(18-1)/1000)*$C$17/10)+(-Assumptions!$B$17*(1+Assumptions!$B$18)^(18-1)))+IF(18<=Assumptions!$B$20,-(Assumptions!$B$7*$D$17)/Assumptions!$B$20,0)+IF(18<=Assumptions!$B$12,IPMT(Assumptions!$B$11,18,Assumptions!$B$12,((Assumptions!$B$7*$D$17)*(1-Assumptions!$B$8))),0))+(-MAX(0,((((Assumptions!$B$5*8760*$B$17*(1-Assumptions!$B$16)^(18-1)/1000)*$C$17/10)+(-Assumptions!$B$17*(1+Assumptions!$B$18)^(18-1)))+IF(18<=Assumptions!$B$20,-(Assumptions!$B$7*$D$17)/Assumptions!$B$20,0)+IF(18<=Assumptions!$B$12,IPMT(Assumptions!$B$11,18,Assumptions!$B$12,((Assumptions!$B$7*$D$17)*(1-Assumptions!$B$8))),0)))*Assumptions!$B$19))-(IF(18<=Assumptions!$B$20,-(Assumptions!$B$7*$D$17)/Assumptions!$B$20,0))+(IF(18<=Assumptions!$B$12,PPMT(Assumptions!$B$11,18,Assumptions!$B$12,((Assumptions!$B$7*$D$17)*(1-Assumptions!$B$8))),0)) -> 2.8603764 | U27: =(((((Assumptions!$B$5*8760*$B$17*(1-Assumptions!$B$16)^(19-1)/1000)*$C$17/10)+(-Assumptions!$B$17*(1+Assumptions!$B$18)^(19-1)))+IF(19<=Assumptions!$B$20,-(Assumptions!$B$7*$D$17)/Assumptions!$B$20,0)+IF(19<=Assumptions!$B$12,IPMT(Assumptions!$B$11,19,Assumptions!$B$12,((Assumptions!$B$7*$D$17)*(1-Assumptions!$B$8))),0))+(-MAX(0,((((Assumptions!$B$5*8760*$B$17*(1-Assumptions!$B$16)^(19-1)/1000)*$C$17/10)+(-Assumptions!$B$17*(1+Assumptions!$B$18)^(19-1)))+IF(19<=Assumptions!$B$20,-(Assumptions!$B$7*$D$17)/Assumptions!$B$20,0)+IF(19<=Assumptions!$B$12,IPMT(Assumptions!$B$11,19,Assumptions!$B$12,((Assumptions!$B$7*$D$17)*(1-Assumptions!$B$8))),0)))*Assumptions!$B$19))-(IF(19<=Assumptions!$B$20,-(Assumptions!$B$7*$D$17)/Assumptions!$B$20,0))+(IF(19<=Assumptions!$B$12,PPMT(Assumptions!$B$11,19,Assumptions!$B$12,((Assumptions!$B$7*$D$17)*(1-Assumptions!$B$8))),0)) -> 2.8006766 | V27: =(((((Assumptions!$B$5*8760*$B$17*(1-Assumptions!$B$16)^(20-1)/1000)*$C$17/10)+(-Assumptions!$B$17*(1+Assumptions!$B$18)^(20-1)))+IF(20<=Assumptions!$B$20,-(Assumptions!$B$7*$D$17)/Assumptions!$B$20,0)+IF(20<=Assumptions!$B$12,IPMT(Assumptions!$B$11,20,Assumptions!$B$12,((Assumptions!$B$7*$D$17)*(1-Assumptions!$B$8))),0))+(-MAX(0,((((Assumptions!$B$5*8760*$B$17*(1-Assumptions!$B$16)^(20-1)/1000)*$C$17/10)+(-Assumptions!$B$17*(1+Assumptions!$B$18)^(20-1)))+IF(20<=Assumptions!$B$20,-(Assumptions!$B$7*$D$17)/Assumptions!$B$20,0)+IF(20<=Assumptions!$B$12,IPMT(Assumptions!$B$11,20,Assumptions!$B$12,((Assumptions!$B$7*$D$17)*(1-Assumptions!$B$8))),0)))*Assumptions!$B$19))-(IF(20<=Assumptions!$B$20,-(Assumptions!$B$7*$D$17)/Assumptions!$B$20,0))+(IF(20<=Assumptions!$B$12,PPMT(Assumptions!$B$11,20,Assumptions!$B$12,((Assumptions!$B$7*$D$17)*(1-Assumptions!$B$8))),0)) -> 2.7389117 | W27: =(((((Assumptions!$B$5*8760*$B$17*(1-Assumptions!$B$16)^(21-1)/1000)*$C$17/10)+(-Assumptions!$B$17*(1+Assumptions!$B$18)^(21-1)))+IF(21<=Assumptions!$B$20,-(Assumptions!$B$7*$D$17)/Assumptions!$B$20,0)+IF(21<=Assumptions!$B$12,IPMT(Assumptions!$B$11,21,Assumptions!$B$12,((Assumptions!$B$7*$D$17)*(1-Assumptions!$B$8))),0))+(-MAX(0,((((Assumptions!$B$5*8760*$B$17*(1-Assumptions!$B$16)^(21-1)/1000)*$C$17/10)+(-Assumptions!$B$17*(1+Assumptions!$B$18)^(21-1)))+IF(21<=Assumptions!$B$20,-(Assumptions!$B$7*$D$17)/Assumptions!$B$20,0)+IF(21<=Assumptions!$B$12,IPMT(Assumptions!$B$11,21,Assumptions!$B$12,((Assumptions!$B$7*$D$17)*(1-Assumptions!$B$8))),0)))*Assumptions!$B$19))-(IF(21<=Assumptions!$B$20,-(Assumptions!$B$7*$D$17)/Assumptions!$B$20,0))+(IF(21<=Assumptions!$B$12,PPMT(Assumptions!$B$11,21,Assumptions!$B$12,((Assumptions!$B$7*$D$17)*(1-Assumptions!$B$8))),0)) -> 2.6749738 | X27: =(((((Assumptions!$B$5*8760*$B$17*(1-Assumptions!$B$16)^(22-1)/1000)*$C$17/10)+(-Assumptions!$B$17*(1+Assumptions!$B$18)^(22-1)))+IF(22<=Assumptions!$B$20,-(Assumptions!$B$7*$D$17)/Assumptions!$B$20,0)+IF(22<=Assumptions!$B$12,IPMT(Assumptions!$B$11,22,Assumptions!$B$12,((Assumptions!$B$7*$D$17)*(1-Assumptions!$B$8))),0))+(-MAX(0,((((Assumptions!$B$5*8760*$B$17*(1-Assumptions!$B$16)^(22-1)/1000)*$C$17/10)+(-Assumptions!$B$17*(1+Assumptions!$B$18)^(22-1)))+IF(22<=Assumptions!$B$20,-(Assumptions!$B$7*$D$17)/Assumptions!$B$20,0)+IF(22<=Assumptions!$B$12,IPMT(Assumptions!$B$11,22,Assumptions!$B$12,((Assumptions!$B$7*$D$17)*(1-Assumptions!$B$8))),0)))*Assumptions!$B$19))-(IF(22<=Assumptions!$B$20,-(Assumptions!$B$7*$D$17)/Assumptions!$B$20,0))+(IF(22<=Assumptions!$B$12,PPMT(Assumptions!$B$11,22,Assumptions!$B$12,((Assumptions!$B$7*$D$17)*(1-Assumptions!$B$8))),0)) -> 2.6087497 | Y27: =(((((Assumptions!$B$5*8760*$B$17*(1-Assumptions!$B$16)^(23-1)/1000)*$C$17/10)+(-Assumptions!$B$17*(1+Assumptions!$B$18)^(23-1)))+IF(23<=Assumptions!$B$20,-(Assumptions!$B$7*$D$17)/Assumptions!$B$20,0)+IF(23<=Assumptions!$B$12,IPMT(Assumptions!$B$11,23,Assumptions!$B$12,((Assumptions!$B$7*$D$17)*(1-Assumptions!$B$8))),0))+(-MAX(0,((((Assumptions!$B$5*8760*$B$17*(1-Assumptions!$B$16)^(23-1)/1000)*$C$17/10)+(-Assumptions!$B$17*(1+Assumptions!$B$18)^(23-1)))+IF(23<=Assumptions!$B$20,-(Assumptions!$B$7*$D$17)/Assumptions!$B$20,0)+IF(23<=Assumptions!$B$12,IPMT(Assumptions!$B$11,23,Assumptions!$B$12,((Assumptions!$B$7*$D$17)*(1-Assumptions!$B$8))),0)))*Assumptions!$B$19))-(IF(23<=Assumptions!$B$20,-(Assumptions!$B$7*$D$17)/Assumptions!$B$20,0))+(IF(23<=Assumptions!$B$12,PPMT(Assumptions!$B$11,23,Assumptions!$B$12,((Assumptions!$B$7*$D$17)*(1-Assumptions!$B$8))),0)) -> 2.5401204 | Z27: =(((((Assumptions!$B$5*8760*$B$17*(1-Assumptions!$B$16)^(24-1)/1000)*$C$17/10)+(-Assumptions!$B$17*(1+Assumptions!$B$18)^(24-1)))+IF(24<=Assumptions!$B$20,-(Assumptions!$B$7*$D$17)/Assumptions!$B$20,0)+IF(24<=Assumptions!$B$12,IPMT(Assumptions!$B$11,24,Assumptions!$B$12,((Assumptions!$B$7*$D$17)*(1-Assumptions!$B$8))),0))+(-MAX(0,((((Assumptions!$B$5*8760*$B$17*(1-Assumptions!$B$16)^(24-1)/1000)*$C$17/10)+(-Assumptions!$B$17*(1+Assumptions!$B$18)^(24-1)))+IF(24<=Assumptions!$B$20,-(Assumptions!$B$7*$D$17)/Assumptions!$B$20,0)+IF(24<=Assumptions!$B$12,IPMT(Assumptions!$B$11,24,Assumptions!$B$12,((Assumptions!$B$7*$D$17)*(1-Assumptions!$B$8))),0)))*Assumptions!$B$19))-(IF(24<=Assumptions!$B$20,-(Assumptions!$B$7*$D$17)/Assumptions!$B$20,0))+(IF(24<=Assumptions!$B$12,PPMT(Assumptions!$B$11,24,Assumptions!$B$12,((Assumptions!$B$7*$D$17)*(1-Assumptions!$B$8))),0)) -> 2.4689613 | AA27: =(((((Assumptions!$B$5*8760*$B$17*(1-Assumptions!$B$16)^(25-1)/1000)*$C$17/10)+(-Assumptions!$B$17*(1+Assumptions!$B$18)^(25-1)))+IF(25<=Assumptions!$B$20,-(Assumptions!$B$7*$D$17)/Assumptions!$B$20,0)+IF(25<=Assumptions!$B$12,IPMT(Assumptions!$B$11,25,Assumptions!$B$12,((Assumptions!$B$7*$D$17)*(1-Assumptions!$B$8))),0))+(-MAX(0,((((Assumptions!$B$5*8760*$B$17*(1-Assumptions!$B$16)^(25-1)/1000)*$C$17/10)+(-Assumptions!$B$17*(1+Assumptions!$B$18)^(25-1)))+IF(25<=Assumptions!$B$20,-(Assumptions!$B$7*$D$17)/Assumptions!$B$20,0)+IF(25<=Assumptions!$B$12,IPMT(Assumptions!$B$11,25,Assumptions!$B$12,((Assumptions!$B$7*$D$17)*(1-Assumptions!$B$8))),0)))*Assumptions!$B$19))-(IF(25<=Assumptions!$B$20,-(Assumptions!$B$7*$D$17)/Assumptions!$B$20,0))+(IF(25<=Assumptions!$B$12,PPMT(Assumptions!$B$11,25,Assumptions!$B$12,((Assumptions!$B$7*$D$17)*(1-Assumptions!$B$8))),0)) -> 2.3951414
